Workbook

Sheet 2021
A1: 2021. év
A3: JANUÁR | B3: 1 | C3: 2 | D3: 3 | E3: 4 | F3: 5 | G3: 6 | H3: 7 | I3: 8 | J3: 9 | K3: 10 | L3: 11 | M3: 12 | N3: 13 | O3: 14 | P3: 15 | Q3: 16 | R3: 17 | S3: 18 | T3: 19 | U3: 20 | V3: 21 | W3: 22 | X3: 23 | Y3: 24 | Z3: 25 | AA3: 26 | AB3: 27 | AC3: 28 | AD3: 29 | AE3: 30 | AF3: 31
B4: P | C4: Szo | D4: V | E4: H | F4: K | G4: Sze | H4: Cs | I4: P | J4: Szo | K4: V | L4: H | M4: K | N4: Sze | O4: Cs | P4: P | Q4: Szo | R4: V | S4: H | T4: K | U4: Sze | V4: Cs | W4: P | X4: Szo | Y4: V | Z4: H | AA4: K | AB4: Sze | AC4: Cs | AD4: P | AE4: Szo | AF4: V
A5: "A" műszak | B5: 2 | C5: 2 | D5: 2 | E5: 2 | F5: X | G5: X | H5: 1 | I5: 1 | J5: 1 | K5: 1 | L5: 1 | M5: 1 | N5: X | O5: X | P5: 3 | Q5: 3 | R5: 3 | S5: 3 | T5: 3 | U5: 3 | V5: X | W5: X | X5: 2 | Y5: 2 | Z5: 2 | AA5: 2 | AB5: 2 | AC5: 2 | AD5: X | AE5: X | AF5: 1
A6: "B" műszak | B6: 3 | C6: 3 | D6: X | E6: X | F6: 2 | G6: 2 | H6: 2 | I6: 2 | J6: 2 | K6: 2 | L6: X | M6: X | N6: 1 | O6: 1 | P6: 1 | Q6: 1 | R6: 1 | S6: 1 | T6: X | U6: X | V6: 3 | W6: 3 | X6: 3 | Y6: 3 | Z6: 3 | AA6: 3 | AB6: X | AC6: X | AD6: 2 | AE6: 2 | AF6: 2
A7: "C" műszak | B7: X | C7: X | D7: 3 | E7: 3 | F7: 3 | G7: 3 | H7: 3 | I7: 3 | J7: X | K7: X | L7: 2 | M7: 2 | N7: 2 | O7: 2 | P7: 2 | Q7: 2 | R7: X | S7: X | T7: 1 | U7: 1 | V7: 1 | W7: 1 | X7: 1 | Y7: 1 | Z7: X | AA7: X | AB7: 3 | AC7: 3 | AD7: 3 | AE7: 3 | AF7: 3
A8: "D" műszak | B8: 1 | C8: 1 | D8: 1 | E8: 1 | F8: 1 | G8: 1 | H8: X | I8: X | J8: 3 | K8: 3 | L8: 3 | M8: 3 | N8: 3 | O8: 3 | P8: X | Q8: X | R8: 2 | S8: 2 | T8: 2 | U8: 2 | V8: 2 | W8: 2 | X8: X | Y8: X | Z8: 1 | AA8: 1 | AB8: 1 | AC8: 1 | AD8: 1 | AE8: 1 | AF8: X
A11: FEBRUÁR | B11: 1 | C11: 2 | D11: 3 | E11: 4 | F11: 5 | G11: 6 | H11: 7 | I11: 8 | J11: 9 | K11: 10 | L11: 11 | M11: 12 | N11: 13 | O11: 14 | P11: 15 | Q11: 16 | R11: 17 | S11: 18 | T11: 19 | U11: 20 | V11: 21 | W11: 22 | X11: 23 | Y11: 24 | Z11: 25 | AA11: 26 | AB11: 27 | AC11: 28
B12: H | C12: K | D12: Sze | E12: Cs | F12: P | G12: Szo | H12: V | I12: H | J12: K | K12: Sze | L12: Cs | M12: P | N12: Szo | O12: V | P12: H | Q12: K | R12: Sze | S12: Cs | T12: P | U12: Szo | V12: V | W12: H | X12: K | Y12: Sze | Z12: Cs | AA12: P | AB12: Szo | AC12: V
A13: "A" műszak | B13: 1 | C13: 1 | D13: 1 | E13: 1 | F13: 1 | G13: X | H13: X | I13: 3 | J13: 3 | K13: 3 | L13: 3 | M13: 3 | N13: 3 | O13: X | P13: X | Q13: 2 | R13: 2 | S13: 2 | T13: 2 | U13: 2 | V13: 2 | W13: X | X13: X | Y13: 1 | Z13: 1 | AA13: 1 | AB13: 1 | AC13: 1
A14: "B" műszak | B14: 2 | C14: 2 | D14: 2 | E14: X | F14: X | G14: 1 | H14: 1 | I14: 1 | J14: 1 | K14: 1 | L14: 1 | M14: X | N14: X | O14: 3 | P14: 3 | Q14: 3 | R14: 3 | S14: 3 | T14: 3 | U14: X | V14: X | W14: 2 | X14: 2 | Y14: 2 | Z14: 2 | AA14: 2 | AB14: 2 | AC14: X
A15: "C" műszak | B15: 3 | C15: X | D15: X | E15: 2 | F15: 2 | G15: 2 | H15: 2 | I15: 2 | J15: 2 | K15: X | L15: X | M15: 1 | N15: 1 | O15: 1 | P15: 1 | Q15: 1 | R15: 1 | S15: X | T15: X | U15: 3 | V15: 3 | W15: 3 | X15: 3 | Y15: 3 | Z15: 3 | AA15: X | AB15: X | AC15: 2
A16: "D" műszak | B16: X | C16: 3 | D16: 3 | E16: 3 | F16: 3 | G16: 3 | H16: 3 | I16: X | J16: X | K16: 2 | L16: 2 | M16: 2 | N16: 2 | O16: 2 | P16: 2 | Q16: X | R16: X | S16: 1 | T16: 1 | U16: 1 | V16: 1 | W16: 1 | X16: 1 | Y16: X | Z16: X | AA16: 3 | AB16: 3 | AC16: 3
A19: MÁRCIUS | B19: 1 | C19: 2 | D19: 3 | E19: 4 | F19: 5 | G19: 6 | H19: 7 | I19: 8 | J19: 9 | K19: 10 | L19: 11 | M19: 12 | N19: 13 | O19: 14 | P19: 15 | Q19: 16 | R19: 17 | S19: 18 | T19: 19 | U19: 20 | V19: 21 | W19: 22 | X19: 23 | Y19: 24 | Z19: 25 | AA19: 26 | AB19: 27 | AC19: 28 | AD19: 29 | AE19: 30 | AF19: 31
B20: H | C20: K | D20: Sze | E20: Cs | F20: P | G20: Szo | H20: V | I20: H | J20: K | K20: Sze | L20: Cs | M20: P | N20: Szo | O20: V | P20: H | Q20: K | R20: Sze | S20: Cs | T20: P | U20: Szo | V20: V | W20: H | X20: K | Y20: Sze | Z20: Cs | AA20: P | AB20: Szo | AC20: V | AD20: H | AE20: K | AF20: Sze
A21: "A" műszak | B21: 1 | C21: X | D21: X | E21: 3 | F21: 3 | G21: 3 | H21: 3 | I21: 3 | J21: 3 | K21: X | L21: X | M21: 2 | N21: 2 | O21: 2 | P21: 2 | Q21: 2 | R21: 2 | S21: X | T21: X | U21: 1 | V21: 1 | W21: 1 | X21: 1 | Y21: 1 | Z21: 1 | AA21: X | AB21: X | AC21: 3 | AD21: 3 | AE21: 3 | AF21: 3
A22: "B" műszak | B22: X | C22: 1 | D22: 1 | E22: 1 | F22: 1 | G22: 1 | H22: 1 | I22: X | J22: X | K22: 3 | L22: 3 | M22: 3 | N22: 3 | O22: 3 | P22: 3 | Q22: X | R22: X | S22: 2 | T22: 2 | U22: 2 | V22: 2 | W22: 2 | X22: 2 | Y22: X | Z22: X | AA22: 1 | AB22: 1 | AC22: 1 | AD22: 1 | AE22: 1 | AF22: 1
A23: "C" műszak | B23: 2 | C23: 2 | D23: 2 | E23: 2 | F23: 2 | G23: X | H23: X | I23: 1 | J23: 1 | K23: 1 | L23: 1 | M23: 1 | N23: 1 | O23: X | P23: X | Q23: 3 | R23: 3 | S23: 3 | T23: 3 | U23: 3 | V23: 3 | W23: X | X23: X | Y23: 2 | Z23: 2 | AA23: 2 | AB23: 2 | AC23: 2 | AD23: 2 | AE23: X | AF23: X
A24: "D" műszak | B24: 3 | C24: 3 | D24: 3 | E24: X | F24: X | G24: 2 | H24: 2 | I24: 2 | J24: 2 | K24: 2 | L24: 2 | M24: X | N24: X | O24: 1 | P24: 1 | Q24: 1 | R24: 1 | S24: 1 | T24: 1 | U24: X | V24: X | W24: 3 | X24: 3 | Y24: 3 | Z24: 3 | AA24: 3 | AB24: 3 | AC24: X | AD24: X | AE24: 2 | AF24: 2
A27: ÁPRILIS | B27: 1 | C27: 2 | D27: 3 | E27: 4 | F27: 5 | G27: 6 | H27: 7 | I27: 8 | J27: 9 | K27: 10 | L27: 11 | M27: 12 | N27: 13 | O27: 14 | P27: 15 | Q27: 16 | R27: 17 | S27: 18 | T27: 19 | U27: 20 | V27: 21 | W27: 22 | X27: 23 | Y27: 24 | Z27: 25 | AA27: 26 | AB27: 27 | AC27: 28 | AD27: 29 | AE27: 30
B28: Cs | C28: P | D28: Szo | E28: V | F28: H | G28: K | H28: Sze | I28: Cs | J28: P | K28: Szo | L28: V | M28: H | N28: K | O28: Sze | P28: Cs | Q28: P | R28: Szo | S28: V | T28: H | U28: K | V28: Sze | W28: Cs | X28: P | Y28: Szo | Z28: V | AA28: H | AB28: K | AC28: Sze | AD28: Cs | AE28: P
A29: "A" műszak | B29: 3 | C29: 3 | D29: X | E29: X | F29: 2 | G29: 2 | H29: 2 | I29: 2 | J29: 2 | K29: 2 | L29: X | M29: X | N29: 1 | O29: 1 | P29: 1 | Q29: 1 | R29: 1 | S29: 1 | T29: X | U29: X | V29: 3 | W29: 3 | X29: 3 | Y29: 3 | Z29: 3 | AA29: 3 | AB29: X | AC29: X | AD29: 2 | AE29: 2
A30: "B" műszak | B30: X | C30: X | D30: 3 | E30: 3 | F30: 3 | G30: 3 | H30: 3 | I30: 3 | J30: X | K30: X | L30: 2 | M30: 2 | N30: 2 | O30: 2 | P30: 2 | Q30: 2 | R30: X | S30: X | T30: 1 | U30: 1 | V30: 1 | W30: 1 | X30: 1 | Y30: 1 | Z30: X | AA30: X | AB30: 3 | AC30: 3 | AD30: 3 | AE30: 3
A31: "C" műszak | B31: 1 | C31: 1 | D31: 1 | E31: 1 | F31: 1 | G31: 1 | H31: X | I31: X | J31: 3 | K31: 3 | L31: 3 | M31: 3 | N31: 3 | O31: 3 | P31: X | Q31: X | R31: 2 | S31: 2 | T31: 2 | U31: 2 | V31: 2 | W31: 2 | X31: X | Y31: X | Z31: 1 | AA31: 1 | AB31: 1 | AC31: 1 | AD31: 1 | AE31: 1
A32: "D" műszak | B32: 2 | C32: 2 | D32: 2 | E32: 2 | F32: X | G32: X | H32: 1 | I32: 1 | J32: 1 | K32: 1 | L32: 1 | M32: 1 | N32: X | O32: X | P32: 3 | Q32: 3 | R32: 3 | S32: 3 | T32: 3 | U32: 3 | V32: X | W32: X | X32: 2 | Y32: 2 | Z32: 2 | AA32: 2 | AB32: 2 | AC32: 2 | AD32: X | AE32: X
A35: MÁJUS | B35: 1 | C35: 2 | D35: 3 | E35: 4 | F35: 5 | G35: 6 | H35: 7 | I35: 8 | J35: 9 | K35: 10 | L35: 11 | M35: 12 | N35: 13 | O35: 14 | P35: 15 | Q35: 16 | R35: 17 | S35: 18 | T35: 19 | U35: 20 | V35: 21 | W35: 22 | X35: 23 | Y35: 24 | Z35: 25 | AA35: 26 | AB35: 27 | AC35: 28 | AD35: 29 | AE35: 30 | AF35: 31
B36: Szo | C36: V | D36: H | E36: K | F36: Sze | G36: Cs | H36: P | I36: Szo | J36: V | K36: H | L36: K | M36: Sze | N36: Cs | O36: P | P36: Szo | Q36: V | R36: H | S36: K | T36: Sze | U36: Cs | V36: P | W36: Szo | X36: V | Y36: H | Z36: K | AA36: Sze | AB36: Cs | AC36: P | AD36: Szo | AE36: V | AF36: H
A37: "A" műszak | B37: 2 | C37: 2 | D37: 2 | E37: 2 | F37: X | G37: X | H37: 1 | I37: 1 | J37: 1 | K37: 1 | L37: 1 | M37: 1 | N37: X | O37: X | P37: 3 | Q37: 3 | R37: 3 | S37: 3 | T37: 3 | U37: 3 | V37: X | W37: X | X37: 2 | Y37: 2 | Z37: 2 | AA37: 2 | AB37: 2 | AC37: 2 | AD37: X | AE37: X | AF37: 1
A38: "B" műszak | B38: 3 | C38: 3 | D38: X | E38: X | F38: 2 | G38: 2 | H38: 2 | I38: 2 | J38: 2 | K38: 2 | L38: X | M38: X | N38: 1 | O38: 1 | P38: 1 | Q38: 1 | R38: 1 | S38: 1 | T38: X | U38: X | V38: 3 | W38: 3 | X38: 3 | Y38: 3 | Z38: 3 | AA38: 3 | AB38: X | AC38: X | AD38: 2 | AE38: 2 | AF38: 2
A39: "C" műszak | B39: X | C39: X | D39: 3 | E39: 3 | F39: 3 | G39: 3 | H39: 3 | I39: 3 | J39: X | K39: X | L39: 2 | M39: 2 | N39: 2 | O39: 2 | P39: 2 | Q39: 2 | R39: X | S39: X | T39: 1 | U39: 1 | V39: 1 | W39: 1 | X39: 1 | Y39: 1 | Z39: X | AA39: X | AB39: 3 | AC39: 3 | AD39: 3 | AE39: 3 | AF39: 3
A40: "D" műszak | B40: 1 | C40: 1 | D40: 1 | E40: 1 | F40: 1 | G40: 1 | H40: X | I40: X | J40: 3 | K40: 3 | L40: 3 | M40: 3 | N40: 3 | O40: 3 | P40: X | Q40: X | R40: 2 | S40: 2 | T40: 2 | U40: 2 | V40: 2 | W40: 2 | X40: X | Y40: X | Z40: 1 | AA40: 1 | AB40: 1 | AC40: 1 | AD40: 1 | AE40: 1 | AF40: X
A43: JÚNIUS | B43: 1 | C43: 2 | D43: 3 | E43: 4 | F43: 5 | G43: 6 | H43: 7 | I43: 8 | J43: 9 | K43: 10 | L43: 11 | M43: 12 | N43: 13 | O43: 14 | P43: 15 | Q43: 16 | R43: 17 | S43: 18 | T43: 19 | U43: 20 | V43: 21 | W43: 22 | X43: 23 | Y43: 24 | Z43: 25 | AA43: 26 | AB43: 27 | AC43: 28 | AD43: 29 | AE43: 30
B44: K | C44: Sze | D44: Cs | E44: P | F44: Szo | G44: V | H44: H | I44: K | J44: Sze | K44: Cs | L44: P | M44: Szo | N44: V | O44: H | P44: K | Q44: Sze | R44: Cs | S44: P | T44: Szo | U44: V | V44: H | W44: K | X44: Sze | Y44: Cs | Z44: P | AA44: Szo | AB44: V | AC44: H | AD44: K | AE44: Sze
A45: "A" műszak | B45: 1 | C45: 1 | D45: 1 | E45: 1 | F45: 1 | G45: X | H45: X | I45: 3 | J45: 3 | K45: 3 | L45: 3 | M45: 3 | N45: 3 | O45: X | P45: X | Q45: 2 | R45: 2 | S45: 2 | T45: 2 | U45: 2 | V45: 2 | W45: X | X45: X | Y45: 1 | Z45: 1 | AA45: 1 | AB45: 1 | AC45: 1 | AD45: 1 | AE45: X
A46: "B" műszak | B46: 2 | C46: 2 | D46: 2 | E46: X | F46: X | G46: 1 | H46: 1 | I46: 1 | J46: 1 | K46: 1 | L46: 1 | M46: X | N46: X | O46: 3 | P46: 3 | Q46: 3 | R46: 3 | S46: 3 | T46: 3 | U46: X | V46: X | W46: 2 | X46: 2 | Y46: 2 | Z46: 2 | AA46: 2 | AB46: 2 | AC46: X | AD46: X | AE46: 1
A47: "C" műszak | B47: 3 | C47: X | D47: X | E47: 2 | F47: 2 | G47: 2 | H47: 2 | I47: 2 | J47: 2 | K47: X | L47: X | M47: 1 | N47: 1 | O47: 1 | P47: 1 | Q47: 1 | R47: 1 | S47: X | T47: X | U47: 3 | V47: 3 | W47: 3 | X47: 3 | Y47: 3 | Z47: 3 | AA47: X | AB47: X | AC47: 2 | AD47: 2 | AE47: 2
A48: "D" műszak | B48: X | C48: 3 | D48: 3 | E48: 3 | F48: 3 | G48: 3 | H48: 3 | I48: X | J48: X | K48: 2 | L48: 2 | M48: 2 | N48: 2 | O48: 2 | P48: 2 | Q48: X | R48: X | S48: 1 | T48: 1 | U48: 1 | V48: 1 | W48: 1 | X48: 1 | Y48: X | Z48: X | AA48: 3 | AB48: 3 | AC48: 3 | AD48: 3 | AE48: 3
A51: JÚLIUS | B51: 1 | C51: 2 | D51: 3 | E51: 4 | F51: 5 | G51: 6 | H51: 7 | I51: 8 | J51: 9 | K51: 10 | L51: 11 | M51: 12 | N51: 13 | O51: 14 | P51: 15 | Q51: 16 | R51: 17 | S51: 18 | T51: 19 | U51: 20 | V51: 21 | W51: 22 | X51: 23 | Y51: 24 | Z51: 25 | AA51: 26 | AB51: 27 | AC51: 28 | AD51: 29 | AE51: 30 | AF51: 31
B52: Cs | C52: P | D52: Szo | E52: V | F52: H | G52: K | H52: Sze | I52: Cs | J52: P | K52: Szo | L52: V | M52: H | N52: K | O52: Sze | P52: Cs | Q52: P | R52: Szo | S52: V | T52: H | U52: K | V52: Sze | W52: Cs | X52: P | Y52: Szo | Z52: V | AA52: H | AB52: K | AC52: Sze | AD52: Cs | AE52: P | AF52: Szo
A53: "A" műszak | B53: X | C53: 3 | D53: 3 | E53: 3 | F53: 3 | G53: 3 | H53: 3 | I53: X | J53: X | K53: 2 | L53: 2 | M53: 2 | N53: 2 | O53: 2 | P53: 2 | Q53: X | R53: X | S53: 1 | T53: 1 | U53: 1 | V53: 1 | W53: 1 | X53: 1 | Y53: X | Z53: X | AA53: 3 | AB53: 3 | AC53: 3 | AD53: 3 | AE53: 3 | AF53: 3
...

Sheet ÖSSZES
A1: N é v | B1: Áth. | C1: Gye-rek | D1: 2021 | E1: Össz. | F1: I. | G1: II. | H1: III. | I1: IV. | J1: V. | K1: VI. | L1: VII | M1: VIII | N1: IX | O1: X | P1: XI | Q1: XII | R1: Szf | S1: M. | U1: I. | V1: II | W1: III | X1: IV | Y1: V | Z1: VI | AA1: VII | AB1: VIII | AC1: IX | AD1: X | AE1: XI | AF1: XII | AG1: + | AH1: M.
F2: szf | G2: szf | H2: szf | I2: szf | J2: szf | K2: szf | L2: szf | M2: szf | N2: szf | O2: szf | P2: szf | Q2: szf | S2: szf | U2: + | V2: + | W2: + | X2: + | Y2: + | Z2: + | AA2: + | AB2: + | AC2: + | AD2: + | AE2: + | AF2: + | AH2: +
A3: Csuka Lajos | D3: 30 | E3: =SUM(B3:D3) -> 30 | F3: =A!AI4 -> 0 | G3: =A!AI28 -> 0 | H3: =A!AI52 -> 0 | I3: =A!AI76 -> 0 | J3: =A!AI100 -> 0 | K3: =A!AI124 -> 0 | L3: =A!AI148 -> 0 | M3: =A!AI172 -> 0 | N3: =A!AI196 -> 0 | O3: =A!AI220 -> 0 | P3: =A!AI244 -> 0 | Q3: =A!AI268 -> 0 | R3: =SUM(F3+G3+H3+I3+J3+K3+L3+M3+N3+O3+P3+Q3) -> 0 | S3: =SUM(E3-R3) -> 30 | U3: =A!AH4 -> 0 | V3: =A!AH28 -> 0 | W3: =A!AH52 -> 0 | X3: =A!AH76 -> 0 | Y3: =A!AH100 -> 0 | Z3: =A!AH124 -> 0 | AA3: =A!AH148 -> 0 | AB3: =A!AH172 -> 0 | AC3: =A!AH196 -> 0 | AD3: =A!AH220 -> 0 | AE3: =A!AH244 -> 0 | AF3: =A!AH268 -> 0 | AG3: =SUM(U3+V3+W3+X3+Y3+Z3+AA3+AB3+AC3+AD3+AE3+AF3) -> 0 | AH3: =SUM(16-AG3) -> 16
A4: Batiz Attila | E4: =SUM(B4:D4) -> 0 | F4: =A!AI5 -> 0 | G4: =A!AI29 -> 0 | H4: =A!AI53 -> 0 | I4: =A!AI77 -> 0 | J4: =A!AI101 -> 0 | K4: =A!AI125 -> 0 | L4: =A!AI149 -> 0 | M4: =A!AI173 -> 0 | N4: =A!AI197 -> 0 | O4: =A!AI221 -> 0 | P4: =A!AI245 -> 0 | Q4: =A!AI269 -> 0 | R4: =SUM(F4+G4+H4+I4+J4+K4+L4+M4+N4+O4+P4+Q4) -> 0 | S4: =SUM(E4-R4) -> 0 | U4: =A!AH5 -> 0 | V4: =A!AH29 -> 0 | W4: =A!AH53 -> 0 | X4: =A!AH77 -> 0 | Y4: =A!AH101 -> 0 | Z4: =A!AH125 -> 0 | AA4: =A!AH149 -> 0 | AB4: =A!AH173 -> 0 | AC4: =A!AH197 -> 0 | AD4: =A!AH221 -> 0 | AE4: =A!AH245 -> 0 | AF4: =A!AH269 -> 0 | AG4: =SUM(U4+V4+W4+X4+Y4+Z4+AA4+AB4+AC4+AD4+AE4+AF4) -> 0 | AH4: =SUM(16-AG4) -> 16
A5: Füredi Antal | E5: =SUM(B5:D5) -> 0 | F5: =A!AI6 -> 0 | G5: =A!AI30 -> 0 | H5: =A!AI54 -> 0 | I5: =A!AI78 -> 0 | J5: =A!AI102 -> 0 | K5: =A!AI126 -> 0 | L5: =A!AI150 -> 0 | M5: =A!AI174 -> 0 | N5: =A!AI198 -> 0 | O5: =A!AI222 -> 0 | P5: =A!AI246 -> 0 | Q5: =A!AI270 -> 0 | R5: =SUM(F5+G5+H5+I5+J5+K5+L5+M5+N5+O5+P5+Q5) -> 0 | S5: =SUM(E5-R5) -> 0 | U5: =A!AH6 -> 0 | V5: =A!AH30 -> 0 | W5: =A!AH54 -> 0 | X5: =A!AH78 -> 0 | Y5: =A!AH102 -> 0 | Z5: =A!AH126 -> 0 | AA5: =A!AH150 -> 0 | AB5: =A!AH174 -> 0 | AC5: =A!AH198 -> 0 | AD5: =A!AH222 -> 0 | AE5: =A!AH246 -> 0 | AF5: =A!AH270 -> 0 | AG5: =SUM(U5+V5+W5+X5+Y5+Z5+AA5+AB5+AC5+AD5+AE5+AF5) -> 0 | AH5: =SUM(16-AG5) -> 16
A6: Iványi István | E6: =SUM(B6:D6) -> 0 | F6: =A!AI7 -> 0 | G6: =A!AI31 -> 0 | H6: =A!AI55 -> 0 | I6: =A!AI79 -> 0 | J6: =A!AI103 -> 0 | K6: =A!AI127 -> 0 | L6: =A!AI151 -> 0 | M6: =A!AI175 -> 0 | N6: =A!AI199 -> 0 | O6: =A!AI223 -> 0 | P6: =A!AI247 -> 0 | Q6: =A!AI271 -> 0 | R6: =SUM(F6+G6+H6+I6+J6+K6+L6+M6+N6+O6+P6+Q6) -> 0 | S6: =SUM(E6-R6) -> 0 | U6: =A!AH7 -> 0 | V6: =A!AH31 -> 0 | W6: =A!AH55 -> 0 | X6: =A!AH79 -> 0 | Y6: =A!AH103 -> 0 | Z6: =A!AH127 -> 0 | AA6: =A!AH151 -> 0 | AB6: =A!AH175 -> 0 | AC6: =A!AH199 -> 0 | AD6: =A!AH223 -> 0 | AE6: =A!AH247 -> 0 | AF6: =A!AH271 -> 0 | AG6: =SUM(U6+V6+W6+X6+Y6+Z6+AA6+AB6+AC6+AD6+AE6+AF6) -> 0 | AH6: =SUM(16-AG6) -> 16
A7: Katonka Tibor | E7: =SUM(B7:D7) -> 0 | F7: =A!AI8 -> 0 | G7: =A!AI32 -> 0 | H7: =A!AI56 -> 0 | I7: =A!AI80 -> 0 | J7: =A!AI104 -> 0 | K7: =A!AI128 -> 0 | L7: =A!AI152 -> 0 | M7: =A!AI176 -> 0 | N7: =A!AI200 -> 0 | O7: =A!AI224 -> 0 | P7: =A!AI248 -> 0 | Q7: =A!AI272 -> 0 | R7: =SUM(F7+G7+H7+I7+J7+K7+L7+M7+N7+O7+P7+Q7) -> 0 | S7: =SUM(E7-R7) -> 0 | U7: =A!AH8 -> 0 | V7: =A!AH32 -> 0 | W7: =A!AH56 -> 0 | X7: =A!AH80 -> 0 | Y7: =A!AH104 -> 0 | Z7: =A!AH128 -> 0 | AA7: =A!AH152 -> 0 | AB7: =A!AH176 -> 0 | AC7: =A!AH200 -> 0 | AD7: =A!AH224 -> 0 | AE7: =A!AH248 -> 0 | AF7: =A!AH272 -> 0 | AG7: =SUM(U7+V7+W7+X7+Y7+Z7+AA7+AB7+AC7+AD7+AE7+AF7) -> 0 | AH7: =SUM(16-AG7) -> 16
A8: Mizsák Péter | E8: =SUM(B8:D8) -> 0 | F8: =A!AI9 -> 0 | G8: =A!AI33 -> 0 | H8: =A!AI57 -> 0 | I8: =A!AI81 -> 0 | J8: =A!AI105 -> 0 | K8: =A!AI129 -> 0 | L8: =A!AI153 -> 0 | M8: =A!AI177 -> 0 | N8: =A!AI201 -> 0 | O8: =A!AI225 -> 0 | P8: =A!AI249 -> 0 | Q8: =A!AI273 -> 0 | R8: =SUM(F8+G8+H8+I8+J8+K8+L8+M8+N8+O8+P8+Q8) -> 0 | S8: =SUM(E8-R8) -> 0 | U8: =A!AH9 -> 0 | V8: =A!AH33 -> 0 | W8: =A!AH57 -> 0 | X8: =A!AH81 -> 0 | Y8: =A!AH105 -> 0 | Z8: =A!AH129 -> 0 | AA8: =A!AH153 -> 0 | AB8: =A!AH177 -> 0 | AC8: =A!AH201 -> 0 | AD8: =A!AH225 -> 0 | AE8: =A!AH249 -> 0 | AF8: =A!AH273 -> 0 | AG8: =SUM(U8+V8+W8+X8+Y8+Z8+AA8+AB8+AC8+AD8+AE8+AF8) -> 0 | AH8: =SUM(16-AG8) -> 16
A9: Vatamány Gergő | E9: =SUM(B9:D9) -> 0 | F9: =A!AI10 -> 0 | G9: =A!AI34 -> 0 | H9: =A!AI58 -> 0 | I9: =A!AI82 -> 0 | J9: =A!AI106 -> 0 | K9: =A!AI130 -> 0 | L9: =A!AI154 -> 0 | M9: =A!AI178 -> 0 | N9: =A!AI202 -> 0 | O9: =A!AI226 -> 0 | P9: =A!AI250 -> 0 | Q9: =A!AI274 -> 0 | R9: =SUM(F9+G9+H9+I9+J9+K9+L9+M9+N9+O9+P9+Q9) -> 0 | S9: =SUM(E9-R9) -> 0 | U9: =A!AH10 -> 0 | V9: =A!AH34 -> 0 | W9: =A!AH58 -> 0 | X9: =A!AH82 -> 0 | Y9: =A!AH106 -> 0 | Z9: =A!AH130 -> 0 | AA9: =A!AH154 -> 0 | AB9: =A!AH178 -> 0 | AC9: =A!AH202 -> 0 | AD9: =A!AH226 -> 0 | AE9: =A!AH250 -> 0 | AF9: =A!AH274 -> 0 | AG9: =SUM(U9+V9+W9+X9+Y9+Z9+AA9+AB9+AC9+AD9+AE9+AF9) -> 0 | AH9: =SUM(16-AG9) -> 16
A10: Név8 | E10: =SUM(B10:D10) -> 0 | F10: =A!AI11 -> 0 | G10: =A!AI35 -> 0 | H10: =A!AI59 -> 0 | I10: =A!AI83 -> 0 | J10: =A!AI107 -> 0 | K10: =A!AI131 -> 0 | L10: =A!AI155 -> 0 | M10: =A!AI179 -> 0 | N10: =A!AI203 -> 0 | O10: =A!AI227 -> 0 | P10: =A!AI251 -> 0 | Q10: =A!AI275 -> 0 | R10: =SUM(F10+G10+H10+I10+J10+K10+L10+M10+N10+O10+P10+Q10) -> 0 | S10: =SUM(E10-R10) -> 0 | U10: =A!AH11 -> 0 | V10: =A!AH35 -> 0 | W10: =A!AH59 -> 0 | X10: =A!AH83 -> 0 | Y10: =A!AH107 -> 0 | Z10: =A!AH131 -> 0 | AA10: =A!AH155 -> 0 | AB10: =A!AH179 -> 0 | AC10: =A!AH203 -> 0 | AD10: =A!AH227 -> 0 | AE10: =A!AH251 -> 0 | AF10: =A!AH275 -> 0 | AG10: =SUM(U10+V10+W10+X10+Y10+Z10+AA10+AB10+AC10+AD10+AE10+AF10) -> 0 | AH10: =SUM(16-AG10) -> 16
A11: Név9 | E11: =SUM(B11:D11) -> 0 | F11: =A!AI12 -> 0 | G11: =A!AI36 -> 0 | H11: =A!AI60 -> 0 | I11: =A!AI84 -> 0 | J11: =A!AI108 -> 0 | K11: =A!AI132 -> 0 | L11: =A!AI156 -> 0 | M11: =A!AI180 -> 0 | N11: =A!AI204 -> 0 | O11: =A!AI228 -> 0 | P11: =A!AI252 -> 0 | Q11: =A!AI276 -> 0 | R11: =SUM(F11+G11+H11+I11+J11+K11+L11+M11+N11+O11+P11+Q11) -> 0 | S11: =SUM(E11-R11) -> 0 | U11: =A!AH12 -> 0 | V11: =A!AH36 -> 0 | W11: =A!AH60 -> 0 | X11: =A!AH84 -> 0 | Y11: =A!AH108 -> 0 | Z11: =A!AH132 -> 0 | AA11: =A!AH156 -> 0 | AB11: =A!AH180 -> 0 | AC11: =A!AH204 -> 0 | AD11: =A!AH228 -> 0 | AE11: =A!AH252 -> 0 | AF11: =A!AH276 -> 0 | AG11: =SUM(U11+V11+W11+X11+Y11+Z11+AA11+AB11+AC11+AD11+AE11+AF11) -> 0 | AH11: =SUM(16-AG11) -> 16
A12: Név10 | E12: =SUM(B12:D12) -> 0 | F12: =A!AI13 -> 0 | G12: =A!AI37 -> 0 | H12: =A!AI61 -> 0 | I12: =A!AI85 -> 0 | J12: =A!AI109 -> 0 | K12: =A!AI133 -> 0 | L12: =A!AI157 -> 0 | M12: =A!AI181 -> 0 | N12: =A!AI205 -> 0 | O12: =A!AI229 -> 0 | P12: =A!AI253 -> 0 | Q12: =A!AI277 -> 0 | R12: =SUM(F12+G12+H12+I12+J12+K12+L12+M12+N12+O12+P12+Q12) -> 0 | S12: =SUM(E12-R12) -> 0 | U12: =A!AH13 -> 0 | V12: =A!AH37 -> 0 | W12: =A!AH61 -> 0 | X12: =A!AH85 -> 0 | Y12: =A!AH109 -> 0 | Z12: =A!AH133 -> 0 | AA12: =A!AH157 -> 0 | AB12: =A!AH181 -> 0 | AC12: =A!AH205 -> 0 | AD12: =A!AH229 -> 0 | AE12: =A!AH253 -> 0 | AF12: =A!AH277 -> 0 | AG12: =SUM(U12+V12+W12+X12+Y12+Z12+AA12+AB12+AC12+AD12+AE12+AF12) -> 0 | AH12: =SUM(16-AG12) -> 16
A13: Név11 | E13: =SUM(B13:D13) -> 0 | F13: =A!AI14 -> 0 | G13: =A!AI38 -> 0 | H13: =A!AI62 -> 0 | I13: =A!AI86 -> 0 | J13: =A!AI110 -> 0 | K13: =A!AI134 -> 0 | L13: =A!AI158 -> 0 | M13: =A!AI182 -> 0 | N13: =A!AI206 -> 0 | O13: =A!AI230 -> 0 | P13: =A!AI254 -> 0 | Q13: =A!AI278 -> 0 | R13: =SUM(F13+G13+H13+I13+J13+K13+L13+M13+N13+O13+P13+Q13) -> 0 | S13: =SUM(E13-R13) -> 0 | U13: =A!AH14 -> 0 | V13: =A!AH38 -> 0 | W13: =A!AH62 -> 0 | X13: =A!AH86 -> 0 | Y13: =A!AH110 -> 0 | Z13: =A!AH134 -> 0 | AA13: =A!AH158 -> 0 | AB13: =A!AH182 -> 0 | AC13: =A!AH206 -> 0 | AD13: =A!AH230 -> 0 | AE13: =A!AH254 -> 0 | AF13: =A!AH278 -> 0 | AG13: =SUM(U13+V13+W13+X13+Y13+Z13+AA13+AB13+AC13+AD13+AE13+AF13) -> 0 | AH13: =SUM(16-AG13) -> 16
A14: Név12 | E14: =SUM(B14:D14) -> 0 | F14: =A!AI15 -> 0 | G14: =A!AI39 -> 0 | H14: =A!AI63 -> 0 | I14: =A!AI87 -> 0 | J14: =A!AI111 -> 0 | K14: =A!AI135 -> 0 | L14: =A!AI159 -> 0 | M14: =A!AI183 -> 0 | N14: =A!AI207 -> 0 | O14: =A!AI231 -> 0 | P14: =A!AI255 -> 0 | Q14: =A!AI279 -> 0 | R14: =SUM(F14+G14+H14+I14+J14+K14+L14+M14+N14+O14+P14+Q14) -> 0 | S14: =SUM(E14-R14) -> 0 | U14: =A!AH15 -> 0 | V14: =A!AH39 -> 0 | W14: =A!AH63 -> 0 | X14: =A!AH87 -> 0 | Y14: =A!AH111 -> 0 | Z14: =A!AH135 -> 0 | AA14: =A!AH159 -> 0 | AB14: =A!AH183 -> 0 | AC14: =A!AH207 -> 0 | AD14: =A!AH231 -> 0 | AE14: =A!AH255 -> 0 | AF14: =A!AH279 -> 0 | AG14: =SUM(U14+V14+W14+X14+Y14+Z14+AA14+AB14+AC14+AD14+AE14+AF14) -> 0 | AH14: =SUM(16-AG14) -> 16
A15: Név13 | E15: =SUM(B15:D15) -> 0 | F15: =A!AI16 -> 0 | G15: =A!AI40 -> 0 | H15: =A!AI64 -> 0 | I15: =A!AI88 -> 0 | J15: =A!AI112 -> 0 | K15: =A!AI136 -> 0 | L15: =A!AI160 -> 0 | M15: =A!AI184 -> 0 | N15: =A!AI208 -> 0 | O15: =A!AI232 -> 0 | P15: =A!AI256 -> 0 | Q15: =A!AI280 -> 0 | R15: =SUM(F15+G15+H15+I15+J15+K15+L15+M15+N15+O15+P15+Q15) -> 0 | S15: =SUM(E15-R15) -> 0 | U15: =A!AH16 -> 0 | V15: =A!AH40 -> 0 | W15: =A!AH64 -> 0 | X15: =A!AH88 -> 0 | Y15: =A!AH112 -> 0 | Z15: =A!AH136 -> 0 | AA15: =A!AH160 -> 0 | AB15: =A!AH184 -> 0 | AC15: =A!AH208 -> 0 | AD15: =A!AH232 -> 0 | AE15: =A!AH256 -> 0 | AF15: =A!AH280 -> 0 | AG15: =SUM(U15+V15+W15+X15+Y15+Z15+AA15+AB15+AC15+AD15+AE15+AF15) -> 0 | AH15: =SUM(16-AG15) -> 16
... A22: Név20 | E22: =SUM(B22:D22) -> 0 | F22: =A!AI23 -> 0 | G22: =A!AI47 -> 0 | H22: =A!AI71 -> 0 | I22: =A!AI95 -> 0 | J22: =A!AI119 -> 0 | K22: =A!AI143 -> 0 | L22: =A!AI167 -> 0 | M22: =A!AI191 -> 0 | N22: =A!AI215 -> 0 | O22: =A!AI239 -> 0 | P22: =A!AI263 -> 0 | Q22: =A!AI287 -> 0 | R22: =SUM(F22+G22+H22+I22+J22+K22+L22+M22+N22+O22+P22+Q22) -> 0 | S22: =SUM(E22-R22) -> 0 | U22: =A!AH23 -> 0 | V22: =A!AH47 -> 0 | W22: =A!AH71 -> 0 | X22: =A!AH95 -> 0 | Y22: =A!AH119 -> 0 | Z22: =A!AH143 -> 0 | AA22: =A!AH167 -> 0 | AB22: =A!AH191 -> 0 | AC22: =A!AH215 -> 0 | AD22: =A!AH239 -> 0 | AE22: =A!AH263 -> 0 | AF22: =A!AH287 -> 0 | AG22: =SUM(U22+V22+W22+X22+Y22+Z22+AA22+AB22+AC22+AD22+AE22+AF22) -> 0 | AH22: =SUM(16-AG22) -> 16
A24: N é v | B24: Áth. | C24: Gye-rek | D24: 2021 | E24: Össz. | F24: I. | G24: II. | H24: III. | I24: IV. | J24: V. | K24: VI. | L24: VII | M24: VIII | N24: IX | O24: X | P24: XI | Q24: XII | R24: Szf | S24: M. | U24: I. | V24: II | W24: III | X24: IV | Y24: V | Z24: VI | AA24: VII | AB24: VIII | AC24: IX | AD24: X | AE24: XI | AF24: XII | AG24: + | AH24: M.
F25: szf | G25: szf | H25: szf | I25: szf | J25: szf | K25: szf | L25: szf | M25: szf | N25: szf | O25: szf | P25: szf | Q25: szf | S25: szf | U25: + | V25: + | W25: + | X25: + | Y25: + | Z25: + | AA25: + | AB25: + | AC25: + | AD25: + | AE25: + | AF25: + | AH25: +
A26: Katona László | E26: =SUM(B26:D26) -> 0 | F26: =B!AI4 -> 0 | G26: =B!AI28 -> 0 | H26: =B!AI52 -> 0 | I26: =B!AI76 -> 0 | J26: =B!AI100 -> 0 | K26: =B!AI124 -> 0 | L26: =B!AI148 -> 0 | M26: =B!AI172 -> 0 | N26: =B!AI196 -> 0 | O26: =B!AI220 -> 0 | P26: =B!AI244 -> 0 | Q26: =B!AI268 -> 0 | R26: =SUM(F26+G26+H26+I26+J26+K26+L26+M26+N26+O26+P26+Q26) -> 0 | S26: =SUM(E26-R26) -> 0 | U26: =B!AH4 -> 0 | V26: =B!AH28 -> 0 | W26: =B!AH52 -> 0 | X26: =B!AH76 -> 0 | Y26: =B!AH100 -> 0 | Z26: =B!AH124 -> 0 | AA26: =B!AH148 -> 0 | AB26: =B!AH172 -> 0 | AC26: =B!AH196 -> 0 | AD26: =B!AH220 -> 0 | AE26: =B!AH244 -> 0 | AF26: =B!AH268 -> 0 | AG26: =SUM(U26+V26+W26+X26+Y26+Z26+AA26+AB26+AC26+AD26+AE26+AF26) -> 0 | AH26: =SUM(16-AG26) -> 16
A27: Fényi László | E27: =SUM(B27:D27) -> 0 | F27: =B!AI5 -> 0 | G27: =B!AI29 -> 0 | H27: =B!AI53 -> 0 | I27: =B!AI77 -> 0 | J27: =B!AI101 -> 0 | K27: =B!AI125 -> 0 | L27: =B!AI149 -> 0 | M27: =B!AI173 -> 0 | N27: =B!AI197 -> 0 | O27: =B!AI221 -> 0 | P27: =B!AI245 -> 0 | Q27: =B!AI269 -> 0 | R27: =SUM(F27+G27+H27+I27+J27+K27+L27+M27+N27+O27+P27+Q27) -> 0 | S27: =SUM(E27-R27) -> 0 | U27: =B!AH5 -> 0 | V27: =B!AH29 -> 0 | W27: =B!AH53 -> 0 | X27: =B!AH77 -> 0 | Y27: =B!AH101 -> 0 | Z27: =B!AH125 -> 0 | AA27: =B!AH149 -> 0 | AB27: =B!AH173 -> 0 | AC27: =B!AH197 -> 0 | AD27: =B!AH221 -> 0 | AE27: =B!AH245 -> 0 | AF27: =B!AH269 -> 0 | AG27: =SUM(U27+V27+W27+X27+Y27+Z27+AA27+AB27+AC27+AD27+AE27+AF27) -> 0 | AH27: =SUM(16-AG27) -> 16
A28: Habara Gábor | E28: =SUM(B28:D28) -> 0 | F28: =B!AI6 -> 0 | G28: =B!AI30 -> 0 | H28: =B!AI54 -> 0 | I28: =B!AI78 -> 0 | J28: =B!AI102 -> 0 | K28: =B!AI126 -> 0 | L28: =B!AI150 -> 0 | M28: =B!AI174 -> 0 | N28: =B!AI198 -> 0 | O28: =B!AI222 -> 0 | P28: =B!AI246 -> 0 | Q28: =B!AI270 -> 0 | R28: =SUM(F28+G28+H28+I28+J28+K28+L28+M28+N28+O28+P28+Q28) -> 0 | S28: =SUM(E28-R28) -> 0 | U28: =B!AH6 -> 0 | V28: =B!AH30 -> 0 | W28: =B!AH54 -> 0 | X28: =B!AH78 -> 0 | Y28: =B!AH102 -> 0 | Z28: =B!AH126 -> 0 | AA28: =B!AH150 -> 0 | AB28: =B!AH174 -> 0 | AC28: =B!AH198 -> 0 | AD28: =B!AH222 -> 0 | AE28: =B!AH246 -> 0 | AF28: =B!AH270 -> 0 | AG28: =SUM(U28+V28+W28+X28+Y28+Z28+AA28+AB28+AC28+AD28+AE28+AF28) -> 0 | AH28: =SUM(16-AG28) -> 16
A29: Holba Imre | D29: 30 | E29: =SUM(B29:D29) -> 30 | F29: =B!AI7 -> 0 | G29: =B!AI31 -> 0 | H29: =B!AI55 -> 0 | I29: =B!AI79 -> 0 | J29: =B!AI103 -> 0 | K29: =B!AI127 -> 0 | L29: =B!AI151 -> 0 | M29: =B!AI175 -> 0 | N29: =B!AI199 -> 0 | O29: =B!AI223 -> 0 | P29: =B!AI247 -> 0 | Q29: =B!AI271 -> 0 | R29: =SUM(F29+G29+H29+I29+J29+K29+L29+M29+N29+O29+P29+Q29) -> 0 | S29: =SUM(E29-R29) -> 30 | U29: =B!AH7 -> 0 | V29: =B!AH31 -> 0 | W29: =B!AH55 -> 0 | X29: =B!AH79 -> 0 | Y29: =B!AH103 -> 0 | Z29: =B!AH127 -> 0 | AA29: =B!AH151 -> 0 | AB29: =B!AH175 -> 0 | AC29: =B!AH199 -> 0 | AD29: =B!AH223 -> 0 | AE29: =B!AH247 -> 0 | AF29: =B!AH271 -> 0 | AG29: =SUM(U29+V29+W29+X29+Y29+Z29+AA29+AB29+AC29+AD29+AE29+AF29) -> 0 | AH29: =SUM(16-AG29) -> 16
A30: Király Bálint Donát | E30: =SUM(B30:D30) -> 0 | F30: =B!AI8 -> 0 | G30: =B!AI32 -> 0 | H30: =B!AI56 -> 0 | I30: =B!AI80 -> 0 | J30: =B!AI104 -> 0 | K30: =B!AI128 -> 0 | L30: =B!AI152 -> 0 | M30: =B!AI176 -> 0 | N30: =B!AI200 -> 0 | O30: =B!AI224 -> 0 | P30: =B!AI248 -> 0 | Q30: =B!AI272 -> 0 | R30: =SUM(F30+G30+H30+I30+J30+K30+L30+M30+N30+O30+P30+Q30) -> 0 | S30: =SUM(E30-R30) -> 0 | U30: =B!AH8 -> 0 | V30: =B!AH32 -> 0 | W30: =B!AH56 -> 0 | X30: =B!AH80 -> 0 | Y30: =B!AH104 -> 0 | Z30: =B!AH128 -> 0 | AA30: =B!AH152 -> 0 | AB30: =B!AH176 -> 0 | AC30: =B!AH200 -> 0 | AD30: =B!AH224 -> 0 | AE30: =B!AH248 -> 0 | AF30: =B!AH272 -> 0 | AG30: =SUM(U30+V30+W30+X30+Y30+Z30+AA30+AB30+AC30+AD30+AE30+AF30) -> 0 | AH30: =SUM(16-AG30) -> 16
A31: Kiss János Tamás | D31: 30 | E31: =SUM(B31:D31) -> 30 | F31: =B!AI9 -> 0 | G31: =B!AI33 -> 0 | H31: =B!AI57 -> 0 | I31: =B!AI81 -> 0 | J31: =B!AI105 -> 0 | K31: =B!AI129 -> 0 | L31: =B!AI153 -> 0 | M31: =B!AI177 -> 0 | N31: =B!AI201 -> 0 | O31: =B!AI225 -> 0 | P31: =B!AI249 -> 0 | Q31: =B!AI273 -> 0 | R31: =SUM(F31+G31+H31+I31+J31+K31+L31+M31+N31+O31+P31+Q31) -> 0 | S31: =SUM(E31-R31) -> 30 | U31: =B!AH9 -> 0 | V31: =B!AH33 -> 0 | W31: =B!AH57 -> 0 | X31: =B!AH81 -> 0 | Y31: =B!AH105 -> 0 | Z31: =B!AH129 -> 0 | AA31: =B!AH153 -> 0 | AB31: =B!AH177 -> 0 | AC31: =B!AH201 -> 0 | AD31: =B!AH225 -> 0 | AE31: =B!AH249 -> 0 | AF31: =B!AH273 -> 0 | AG31: =SUM(U31+V31+W31+X31+Y31+Z31+AA31+AB31+AC31+AD31+AE31+AF31) -> 0 | AH31: =SUM(16-AG31) -> 16
A32: Mezei Lajos | D32: 30 | E32: =SUM(B32:D32) -> 30 | F32: =B!AI10 -> 0 | G32: =B!AI34 -> 0 | H32: =B!AI58 -> 0 | I32: =B!AI82 -> 0 | J32: =B!AI106 -> 0 | K32: =B!AI130 -> 0 | L32: =B!AI154 -> 0 | M32: =B!AI178 -> 0 | N32: =B!AI202 -> 0 | O32: =B!AI226 -> 0 | P32: =B!AI250 -> 0 | Q32: =B!AI274 -> 0 | R32: =SUM(F32+G32+H32+I32+J32+K32+L32+M32+N32+O32+P32+Q32) -> 0 | S32: =SUM(E32-R32) -> 30 | U32: =B!AH10 -> 0 | V32: =B!AH34 -> 0 | W32: =B!AH58 -> 0 | X32: =B!AH82 -> 0 | Y32: =B!AH106 -> 0 | Z32: =B!AH130 -> 0 | AA32: =B!AH154 -> 0 | AB32: =B!AH178 -> 0 | AC32: =B!AH202 -> 0 | AD32: =B!AH226 -> 0 | AE32: =B!AH250 -> 0 | AF32: =B!AH274 -> 0 | AG32: =SUM(U32+V32+W32+X32+Y32+Z32+AA32+AB32+AC32+AD32+AE32+AF32) -> 0 | AH32: =SUM(16-AG32) -> 16
A33: Név8 | E33: =SUM(B33:D33) -> 0 | F33: =B!AI11 -> 0 | G33: =B!AI35 -> 0 | H33: =B!AI59 -> 0 | I33: =B!AI83 -> 0 | J33: =B!AI107 -> 0 | K33: =B!AI131 -> 0 | L33: =B!AI155 -> 0 | M33: =B!AI179 -> 0 | N33: =B!AI203 -> 0 | O33: =B!AI227 -> 0 | P33: =B!AI251 -> 0 | Q33: =B!AI275 -> 0 | R33: =SUM(F33+G33+H33+I33+J33+K33+L33+M33+N33+O33+P33+Q33) -> 0 | S33: =SUM(E33-R33) -> 0 | U33: =B!AH11 -> 0 | V33: =B!AH35 -> 0 | W33: =B!AH59 -> 0 | X33: =B!AH83 -> 0 | Y33: =B!AH107 -> 0 | Z33: =B!AH131 -> 0 | AA33: =B!AH155 -> 0 | AB33: =B!AH179 -> 0 | AC33: =B!AH203 -> 0 | AD33: =B!AH227 -> 0 | AE33: =B!AH251 -> 0 | AF33: =B!AH275 -> 0 | AG33: =SUM(U33+V33+W33+X33+Y33+Z33+AA33+AB33+AC33+AD33+AE33+AF33) -> 0 | AH33: =SUM(16-AG33) -> 16
A34: Név9 | E34: =SUM(B34:D34) -> 0 | F34: =B!AI12 -> 0 | G34: =B!AI36 -> 0 | H34: =B!AI60 -> 0 | I34: =B!AI84 -> 0 | J34: =B!AI108 -> 0 | K34: =B!AI132 -> 0 | L34: =B!AI156 -> 0 | M34: =B!AI180 -> 0 | N34: =B!AI204 -> 0 | O34: =B!AI228 -> 0 | P34: =B!AI252 -> 0 | Q34: =B!AI276 -> 0 | R34: =SUM(F34+G34+H34+I34+J34+K34+L34+M34+N34+O34+P34+Q34) -> 0 | S34: =SUM(E34-R34) -> 0 | U34: =B!AH12 -> 0 | V34: =B!AH36 -> 0 | W34: =B!AH60 -> 0 | X34: =B!AH84 -> 0 | Y34: =B!AH108 -> 0 | Z34: =B!AH132 -> 0 | AA34: =B!AH156 -> 0 | AB34: =B!AH180 -> 0 | AC34: =B!AH204 -> 0 | AD34: =B!AH228 -> 0 | AE34: =B!AH252 -> 0 | AF34: =B!AH276 -> 0 | AG34: =SUM(U34+V34+W34+X34+Y34+Z34+AA34+AB34+AC34+AD34+AE34+AF34) -> 0 | AH34: =SUM(16-AG34) -> 16
A35: Név10 | E35: =SUM(B35:D35) -> 0 | F35: =B!AI13 -> 0 | G35: =B!AI37 -> 0 | H35: =B!AI61 -> 0 | I35: =B!AI85 -> 0 | J35: =B!AI109 -> 0 | K35: =B!AI133 -> 0 | L35: =B!AI157 -> 0 | M35: =B!AI181 -> 0 | N35: =B!AI205 -> 0 | O35: =B!AI229 -> 0 | P35: =B!AI253 -> 0 | Q35: =B!AI277 -> 0 | R35: =SUM(F35+G35+H35+I35+J35+K35+L35+M35+N35+O35+P35+Q35) -> 0 | S35: =SUM(E35-R35) -> 0 | U35: =B!AH13 -> 0 | V35: =B!AH37 -> 0 | W35: =B!AH61 -> 0 | X35: =B!AH85 -> 0 | Y35: =B!AH109 -> 0 | Z35: =B!AH133 -> 0 | AA35: =B!AH157 -> 0 | AB35: =B!AH181 -> 0 | AC35: =B!AH205 -> 0 | AD35: =B!AH229 -> 0 | AE35: =B!AH253 -> 0 | AF35: =B!AH277 -> 0 | AG35: =SUM(U35+V35+W35+X35+Y35+Z35+AA35+AB35+AC35+AD35+AE35+AF35) -> 0 | AH35: =SUM(16-AG35) -> 16
A36: Név11 | E36: =SUM(B36:D36) -> 0 | F36: =B!AI14 -> 0 | G36: =B!AI38 -> 0 | H36: =B!AI62 -> 0 | I36: =B!AI86 -> 0 | J36: =B!AI110 -> 0 | K36: =B!AI134 -> 0 | L36: =B!AI158 -> 0 | M36: =B!AI182 -> 0 | N36: =B!AI206 -> 0 | O36: =B!AI230 -> 0 | P36: =B!AI254 -> 0 | Q36: =B!AI278 -> 0 | R36: =SUM(F36+G36+H36+I36+J36+K36+L36+M36+N36+O36+P36+Q36) -> 0 | S36: =SUM(E36-R36) -> 0 | U36: =B!AH14 -> 0 | V36: =B!AH38 -> 0 | W36: =B!AH62 -> 0 | X36: =B!AH86 -> 0 | Y36: =B!AH110 -> 0 | Z36: =B!AH134 -> 0 | AA36: =B!AH158 -> 0 | AB36: =B!AH182 -> 0 | AC36: =B!AH206 -> 0 | AD36: =B!AH230 -> 0 | AE36: =B!AH254 -> 0 | AF36: =B!AH278 -> 0 | AG36: =SUM(U36+V36+W36+X36+Y36+Z36+AA36+AB36+AC36+AD36+AE36+AF36) -> 0 | AH36: =SUM(16-AG36) -> 16
A37: Név12 | E37: =SUM(B37:D37) -> 0 | F37: =B!AI15 -> 0 | G37: =B!AI39 -> 0 | H37: =B!AI63 -> 0 | I37: =B!AI87 -> 0 | J37: =B!AI111 -> 0 | K37: =B!AI135 -> 0 | L37: =B!AI159 -> 0 | M37: =B!AI183 -> 0 | N37: =B!AI207 -> 0 | O37: =B!AI231 -> 0 | P37: =B!AI255 -> 0 | Q37: =B!AI279 -> 0 | R37: =SUM(F37+G37+H37+I37+J37+K37+L37+M37+N37+O37+P37+Q37) -> 0 | S37: =SUM(E37-R37) -> 0 | U37: =B!AH15 -> 0 | V37: =B!AH39 -> 0 | W37: =B!AH63 -> 0 | X37: =B!AH87 -> 0 | Y37: =B!AH111 -> 0 | Z37: =B!AH135 -> 0 | AA37: =B!AH159 -> 0 | AB37: =B!AH183 -> 0 | AC37: =B!AH207 -> 0 | AD37: =B!AH231 -> 0 | AE37: =B!AH255 -> 0 | AF37: =B!AH279 -> 0 | AG37: =SUM(U37+V37+W37+X37+Y37+Z37+AA37+AB37+AC37+AD37+AE37+AF37) -> 0 | AH37: =SUM(16-AG37) -> 16
A38: Név13 | E38: =SUM(B38:D38) -> 0 | F38: =B!AI16 -> 0 | G38: =B!AI40 -> 0 | H38: =B!AI64 -> 0 | I38: =B!AI88 -> 0 | J38: =B!AI112 -> 0 | K38: =B!AI136 -> 0 | L38: =B!AI160 -> 0 | M38: =B!AI184 -> 0 | N38: =B!AI208 -> 0 | O38: =B!AI232 -> 0 | P38: =B!AI256 -> 0 | Q38: =B!AI280 -> 0 | R38: =SUM(F38+G38+H38+I38+J38+K38+L38+M38+N38+O38+P38+Q38) -> 0 | S38: =SUM(E38-R38) -> 0 | U38: =B!AH16 -> 0 | V38: =B!AH40 -> 0 | W38: =B!AH64 -> 0 | X38: =B!AH88 -> 0 | Y38: =B!AH112 -> 0 | Z38: =B!AH136 -> 0 | AA38: =B!AH160 -> 0 | AB38: =B!AH184 -> 0 | AC38: =B!AH208 -> 0 | AD38: =B!AH232 -> 0 | AE38: =B!AH256 -> 0 | AF38: =B!AH280 -> 0 | AG38: =SUM(U38+V38+W38+X38+Y38+Z38+AA38+AB38+AC38+AD38+AE38+AF38) -> 0 | AH38: =SUM(16-AG38) -> 16
A39: Név14 | E39: =SUM(B39:D39) -> 0 | F39: =B!AI17 -> 0 | G39: =B!AI41 -> 0 | H39: =B!AI65 -> 0 | I39: =B!AI89 -> 0 | J39: =B!AI113 -> 0 | K39: =B!AI137 -> 0 | L39: =B!AI161 -> 0 | M39: =B!AI185 -> 0 | N39: =B!AI209 -> 0 | O39: =B!AI233 -> 0 | P39: =B!AI257 -> 0 | Q39: =B!AI281 -> 0 | R39: =SUM(F39+G39+H39+I39+J39+K39+L39+M39+N39+O39+P39+Q39) -> 0 | S39: =SUM(E39-R39) -> 0 | U39: =B!AH17 -> 0 | V39: =B!AH41 -> 0 | W39: =B!AH65 -> 0 | X39: =B!AH89 -> 0 | Y39: =B!AH113 -> 0 | Z39: =B!AH137 -> 0 | AA39: =B!AH161 -> 0 | AB39: =B!AH185 -> 0 | AC39: =B!AH209 -> 0 | AD39: =B!AH233 -> 0 | AE39: =B!AH257 -> 0 | AF39: =B!AH281 -> 0 | AG39: =SUM(U39+V39+W39+X39+Y39+Z39+AA39+AB39+AC39+AD39+AE39+AF39) -> 0 | AH39: =SUM(16-AG39) -> 16
A40: Név15 | E40: =SUM(B40:D40) -> 0 | F40: =B!AI18 -> 0 | G40: =B!AI42 -> 0 | H40: =B!AI66 -> 0 | I40: =B!AI90 -> 0 | J40: =B!AI114 -> 0 | K40: =B!AI138 -> 0 | L40: =B!AI162 -> 0 | M40: =B!AI186 -> 0 | N40: =B!AI210 -> 0 | O40: =B!AI234 -> 0 | P40: =B!AI258 -> 0 | Q40: =B!AI282 -> 0 | R40: =SUM(F40+G40+H40+I40+J40+K40+L40+M40+N40+O40+P40+Q40) -> 0 | S40: =SUM(E40-R40) -> 0 | U40: =B!AH18 -> 0 | V40: =B!AH42 -> 0 | W40: =B!AH66 -> 0 | X40: =B!AH90 -> 0 | Y40: =B!AH114 -> 0 | Z40: =B!AH138 -> 0 | AA40: =B!AH162 -> 0 | AB40: =B!AH186 -> 0 | AC40: =B!AH210 -> 0 | AD40: =B!AH234 -> 0 | AE40: =B!AH258 -> 0 | AF40: =B!AH282 -> 0 | AG40: =SUM(U40+V40+W40+X40+Y40+Z40+AA40+AB40+AC40+AD40+AE40+AF40) -> 0 | AH40: =SUM(16-AG40) -> 16
A41: Név16 | E41: =SUM(B41:D41) -> 0 | F41: =B!AI19 -> 0 | G41: =B!AI43 -> 0 | H41: =B!AI67 -> 0 | I41: =B!AI91 -> 0 | J41: =B!AI115 -> 0 | K41: =B!AI139 -> 0 | L41: =B!AI163 -> 0 | M41: =B!AI187 -> 0 | N41: =B!AI211 -> 0 | O41: =B!AI235 -> 0 | P41: =B!AI259 -> 0 | Q41: =B!AI283 -> 0 | R41: =SUM(F41+G41+H41+I41+J41+K41+L41+M41+N41+O41+P41+Q41) -> 0 | S41: =SUM(E41-R41) -> 0 | U41: =B!AH19 -> 0 | V41: =B!AH43 -> 0 | W41: =B!AH67 -> 0 | X41: =B!AH91 -> 0 | Y41: =B!AH115 -> 0 | Z41: =B!AH139 -> 0 | AA41: =B!AH163 -> 0 | AB41: =B!AH187 -> 0 | AC41: =B!AH211 -> 0 | AD41: =B!AH235 -> 0 | AE41: =B!AH259 -> 0 | AF41: =B!AH283 -> 0 | AG41: =SUM(U41+V41+W41+X41+Y41+Z41+AA41+AB41+AC41+AD41+AE41+AF41) -> 0 | AH41: =SUM(16-AG41) -> 16
A42: Név17 | E42: =SUM(B42:D42) -> 0 | F42: =B!AI20 -> 0 | G42: =B!AI44 -> 0 | H42: =B!AI68 -> 0 | I42: =B!AI92 -> 0 | J42: =B!AI116 -> 0 | K42: =B!AI140 -> 0 | L42: =B!AI164 -> 0 | M42: =B!AI188 -> 0 | N42: =B!AI212 -> 0 | O42: =B!AI236 -> 0 | P42: =B!AI260 -> 0 | Q42: =B!AI284 -> 0 | R42: =SUM(F42+G42+H42+I42+J42+K42+L42+M42+N42+O42+P42+Q42) -> 0 | S42: =SUM(E42-R42) -> 0 | U42: =B!AH20 -> 0 | V42: =B!AH44 -> 0 | W42: =B!AH68 -> 0 | X42: =B!AH92 -> 0 | Y42: =B!AH116 -> 0 | Z42: =B!AH140 -> 0 | AA42: =B!AH164 -> 0 | AB42: =B!AH188 -> 0 | AC42: =B!AH212 -> 0 | AD42: =B!AH236 -> 0 | AE42: =B!AH260 -> 0 | AF42: =B!AH284 -> 0 | AG42: =SUM(U42+V42+W42+X42+Y42+Z42+AA42+AB42+AC42+AD42+AE42+AF42) -> 0 | AH42: =SUM(16-AG42) -> 16
A43: Név18 | E43: =SUM(B43:D43) -> 0 | F43: =B!AI21 -> 0 | G43: =B!AI45 -> 0 | H43: =B!AI69 -> 0 | I43: =B!AI93 -> 0 | J43: =B!AI117 -> 0 | K43: =B!AI141 -> 0 | L43: =B!AI165 -> 0 | M43: =B!AI189 -> 0 | N43: =B!AI213 -> 0 | O43: =B!AI237 -> 0 | P43: =B!AI261 -> 0 | Q43: =B!AI285 -> 0 | R43: =SUM(F43+G43+H43+I43+J43+K43+L43+M43+N43+O43+P43+Q43) -> 0 | S43: =SUM(E43-R43) -> 0 | U43: =B!AH21 -> 0 | V43: =B!AH45 -> 0 | W43: =B!AH69 -> 0 | X43: =B!AH93 -> 0 | Y43: =B!AH117 -> 0 | Z43: =B!AH141 -> 0 | AA43: =B!AH165 -> 0 | AB43: =B!AH189 -> 0 | AC43: =B!AH213 -> 0 | AD43: =B!AH237 -> 0 | AE43: =B!AH261 -> 0 | AF43: =B!AH285 -> 0 | AG43: =SUM(U43+V43+W43+X43+Y43+Z43+AA43+AB43+AC43+AD43+AE43+AF43) -> 0 | AH43: =SUM(16-AG43) -> 16
A44: Név19 | E44: =SUM(B44:D44) -> 0 | F44: =B!AI22 -> 0 | G44: =B!AI46 -> 0 | H44: =B!AI70 -> 0 | I44: =B!AI94 -> 0 | J44: =B!AI118 -> 0 | K44: =B!AI142 -> 0 | L44: =B!AI166 -> 0 | M44: =B!AI190 -> 0 | N44: =B!AI214 -> 0 | O44: =B!AI238 -> 0 | P44: =B!AI262 -> 0 | Q44: =B!AI286 -> 0 | R44: =SUM(F44+G44+H44+I44+J44+K44+L44+M44+N44+O44+P44+Q44) -> 0 | S44: =SUM(E44-R44) -> 0 | U44: =B!AH22 -> 0 | V44: =B!AH46 -> 0 | W44: =B!AH70 -> 0 | X44: =B!AH94 -> 0 | Y44: =B!AH118 -> 0 | Z44: =B!AH142 -> 0 | AA44: =B!AH166 -> 0 | AB44: =B!AH190 -> 0 | AC44: =B!AH214 -> 0 | AD44: =B!AH238 -> 0 | AE44: =B!AH262 -> 0 | AF44: =B!AH286 -> 0 | AG44: =SUM(U44+V44+W44+X44+Y44+Z44+AA44+AB44+AC44+AD44+AE44+AF44) -> 0 | AH44: =SUM(16-AG44) -> 16
A45: Név20 | E45: =SUM(B45:D45) -> 0 | F45: =B!AI23 -> 0 | G45: =B!AI47 -> 0 | H45: =B!AI71 -> 0 | I45: =B!AI95 -> 0 | J45: =B!AI119 -> 0 | K45: =B!AI143 -> 0 | L45: =B!AI167 -> 0 | M45: =B!AI191 -> 0 | N45: =B!AI215 -> 0 | O45: =B!AI239 -> 0 | P45: =B!AI263 -> 0 | Q45: =B!AI287 -> 0 | R45: =SUM(F45+G45+H45+I45+J45+K45+L45+M45+N45+O45+P45+Q45) -> 0 | S45: =SUM(E45-R45) -> 0 | U45: =B!AH23 -> 0 | V45: =B!AH47 -> 0 | W45: =B!AH71 -> 0 | X45: =B!AH95 -> 0 | Y45: =B!AH119 -> 0 | Z45: =B!AH143 -> 0 | AA45: =B!AH167 -> 0 | AB45: =B!AH191 -> 0 | AC45: =B!AH215 -> 0 | AD45: =B!AH239 -> 0 | AE45: =B!AH263 -> 0 | AF45: =B!AH287 -> 0 | AG45: =SUM(U45+V45+W45+X45+Y45+Z45+AA45+AB45+AC45+AD45+AE45+AF45) -> 0 | AH45: =SUM(16-AG45) -> 16
A47: N é v | B47: Áth. | C47: Gye-rek | D47: 2021 | E47: Össz. | F47: I. | G47: II. | H47: III. | I47: IV. | J47: V. | K47: VI. | L47: VII | M47: VIII | N47: IX | O47: X | P47: XI | Q47: XII | R47: Szf | S47: M. | U47: I. | V47: II | W47: III | X47: IV | Y47: V | Z47: VI | AA47: VII | AB47: VIII | AC47: IX | AD47: X | AE47: XI | AF47: XII | AG47: + | AH47: M.
F48: szf | G48: szf | H48: szf | I48: szf | J48: szf | K48: szf | L48: szf | M48: szf | N48: szf | O48: szf | P48: szf | Q48: szf | S48: szf | U48: + | V48: + | W48: + | X48: + | Y48: + | Z48: + | AA48: + | AB48: + | AC48: + | AD48: + | AE48: + | AF48: + | AH48: +
...

Sheet A
A1: JANUÁR | B1: 1 | C1: 2 | D1: 3 | E1: 4 | F1: 5 | G1: 6 | H1: 7 | I1: 8 | J1: 9 | K1: 10 | L1: 11 | M1: 12 | N1: 13 | O1: 14 | P1: 15 | Q1: 16 | R1: 17 | S1: 18 | T1: 19 | U1: 20 | V1: 21 | W1: 22 | X1: 23 | Y1: 24 | Z1: 25 | AA1: 26 | AB1: 27 | AC1: 28 | AD1: 29 | AE1: 30 | AF1: 31 | AH1: + | AI1: SZF
B2: ='2021'!B4 -> P | C2: ='2021'!C4 -> Szo | D2: ='2021'!D4 -> V | E2: ='2021'!E4 -> H | F2: ='2021'!F4 -> K | G2: ='2021'!G4 -> Sze | H2: ='2021'!H4 -> Cs | I2: ='2021'!I4 -> P | ... AF2: ='2021'!AF4 -> V
B3: ='2021'!B5 -> 2 | C3: ='2021'!C5 -> 2 | D3: ='2021'!D5 -> 2 | E3: ='2021'!E5 -> 2 | F3: ='2021'!F5 -> X | G3: X | H3: ='2021'!H5 -> 1 | I3: ='2021'!I5 -> 1 | J3: ='2021'!J5 -> 1 | K3: ='2021'!K5 -> 1 | L3: ='2021'!L5 -> 1 | M3: ='2021'!M5 -> 1 | N3: ='2021'!N5 -> X | O3: ='2021'!O5 -> X | ... AF3: ='2021'!AF5 -> 1
A4: =ÖSSZES!$A$3 -> Csuka Lajos | F4: X | G4: X | N4: X | O4: X | V4: X | W4: X | AD4: X | AE4: X | AH4: =1*COUNTIF(A4:AF4,"+") -> 0 | AI4: =1*COUNTIF(B4:AF4,"szf") -> 0
A5: =ÖSSZES!$A$4 -> Batiz Attila | F5: X | G5: X | N5: X | O5: X | V5: X | W5: X | AD5: X | AE5: X | AH5: =1*COUNTIF(A5:AF5,"+") -> 0 | AI5: =1*COUNTIF(B5:AF5,"szf") -> 0
A6: =ÖSSZES!$A$5 -> Füredi Antal | F6: X | G6: X | N6: X | O6: X | V6: X | W6: X | AD6: X | AE6: X | AH6: =1*COUNTIF(A6:AF6,"+") -> 0 | AI6: =1*COUNTIF(B6:AF6,"szf") -> 0
A7: =ÖSSZES!$A$6 -> Iványi István | F7: X | G7: X | N7: X | O7: X | V7: X | W7: X | AD7: X | AE7: X | AH7: =1*COUNTIF(A7:AF7,"+") -> 0 | AI7: =1*COUNTIF(B7:AF7,"szf") -> 0
A8: =ÖSSZES!$A$7 -> Katonka Tibor | F8: X | G8: X | N8: X | O8: X | V8: X | W8: X | AD8: X | AE8: X | AH8: =1*COUNTIF(A8:AF8,"+") -> 0 | AI8: =1*COUNTIF(B8:AF8,"szf") -> 0
A9: =ÖSSZES!$A$8 -> Mizsák Péter | F9: X | G9: X | N9: X | O9: X | V9: X | W9: X | AD9: X | AE9: X | AH9: =1*COUNTIF(A9:AF9,"+") -> 0 | AI9: =1*COUNTIF(B9:AF9,"szf") -> 0
A10: =ÖSSZES!$A$9 -> Vatamány Gergő | F10: X | G10: X | N10: X | O10: X | V10: X | W10: X | AD10: X | AE10: X | AH10: =1*COUNTIF(A10:AF10,"+") -> 0 | AI10: =1*COUNTIF(B10:AF10,"szf") -> 0
A11: =ÖSSZES!$A$10 -> Név8 | F11: X | G11: X | N11: X | O11: X | V11: X | W11: X | AD11: X | AE11: X | AH11: =1*COUNTIF(A11:AF11,"+") -> 0 | AI11: =1*COUNTIF(B11:AF11,"szf") -> 0
A12: =ÖSSZES!$A$11 -> Név9 | F12: X | G12: X | N12: X | O12: X | V12: X | W12: X | AD12: X | AE12: X | AH12: =1*COUNTIF(A12:AF12,"+") -> 0 | AI12: =1*COUNTIF(B12:AF12,"szf") -> 0
A13: =ÖSSZES!$A$12 -> Név10 | F13: X | G13: X | N13: X | O13: X | V13: X | W13: X | AD13: X | AE13: X | AH13: =1*COUNTIF(A13:AF13,"+") -> 0 | AI13: =1*COUNTIF(B13:AF13,"szf") -> 0
A14: =ÖSSZES!$A$13 -> Név11 | F14: X | G14: X | N14: X | O14: X | V14: X | W14: X | AD14: X | AE14: X | AH14: =1*COUNTIF(A14:AF14,"+") -> 0 | AI14: =1*COUNTIF(B14:AF14,"szf") -> 0
A15: =ÖSSZES!$A$14 -> Név12 | F15: X | G15: X | N15: X | O15: X | V15: X | W15: X | AD15: X | AE15: X | AH15: =1*COUNTIF(A15:AF15,"+") -> 0 | AI15: =1*COUNTIF(B15:AF15,"szf") -> 0
A16: =ÖSSZES!$A$15 -> Név13 | F16: X | G16: X | N16: X | O16: X | V16: X | W16: X | AD16: X | AE16: X | AH16: =1*COUNTIF(A16:AF16,"+") -> 0 | AI16: =1*COUNTIF(B16:AF16,"szf") -> 0
A17: =ÖSSZES!$A$16 -> Név14 | F17: X | G17: X | N17: X | O17: X | V17: X | W17: X | AD17: X | AE17: X | AH17: =1*COUNTIF(A17:AF17,"+") -> 0 | AI17: =1*COUNTIF(B17:AF17,"szf") -> 0
A18: =ÖSSZES!$A$17 -> Név15 | F18: X | G18: X | N18: X | O18: X | V18: X | W18: X | AD18: X | AE18: X | AH18: =1*COUNTIF(A18:AF18,"+") -> 0 | AI18: =1*COUNTIF(B18:AF18,"szf") -> 0
A19: =ÖSSZES!$A$18 -> Név16 | F19: X | G19: X | N19: X | O19: X | V19: X | W19: X | AD19: X | AE19: X | AH19: =1*COUNTIF(A19:AF19,"+") -> 0 | AI19: =1*COUNTIF(B19:AF19,"szf") -> 0
A20: =ÖSSZES!$A$19 -> Név17 | F20: X | G20: X | N20: X | O20: X | V20: X | W20: X | AD20: X | AE20: X | AH20: =1*COUNTIF(A20:AF20,"+") -> 0 | AI20: =1*COUNTIF(B20:AF20,"szf") -> 0
A21: =ÖSSZES!$A$20 -> Név18 | F21: X | G21: X | N21: X | O21: X | V21: X | W21: X | AD21: X | AE21: X | AH21: =1*COUNTIF(A21:AF21,"+") -> 0 | AI21: =1*COUNTIF(B21:AF21,"szf") -> 0
A22: =ÖSSZES!$A$21 -> Név19 | F22: X | G22: X | N22: X | O22: X | V22: X | W22: X | AD22: X | AE22: X | AH22: =1*COUNTIF(A22:AF22,"+") -> 0 | AI22: =1*COUNTIF(B22:AF22,"szf") -> 0
A23: =ÖSSZES!$A$22 -> Név20 | F23: X | G23: X | N23: X | O23: X | V23: X | W23: X | AD23: X | AE23: X | AH23: =1*COUNTIF(A23:AF23,"+") -> 0 | AI23: =1*COUNTIF(B23:AF23,"szf") -> 0
A25: FEBRUÁR | B25: 1 | C25: 2 | D25: 3 | E25: 4 | F25: 5 | G25: 6 | H25: 7 | I25: 8 | J25: 9 | K25: 10 | L25: 11 | M25: 12 | N25: 13 | O25: 14 | P25: 15 | Q25: 16 | R25: 17 | S25: 18 | T25: 19 | U25: 20 | V25: 21 | W25: 22 | X25: 23 | Y25: 24 | Z25: 25 | AA25: 26 | AB25: 27 | AC25: 28 | AH25: + | AI25: SZF
B26: ='2021'!B12 -> H | C26: ='2021'!C12 -> K | D26: ='2021'!D12 -> Sze | E26: ='2021'!E12 -> Cs | F26: ='2021'!F12 -> P | G26: ='2021'!G12 -> Szo | H26: ='2021'!H12 -> V | I26: ='2021'!I12 -> H | ... AC26: ='2021'!AC12 -> V
B27: ='2021'!B13 -> 1 | C27: ='2021'!C13 -> 1 | D27: ='2021'!D13 -> 1 | E27: ='2021'!E13 -> 1 | F27: ='2021'!F13 -> 1 | G27: ='2021'!G13 -> X | H27: ='2021'!H13 -> X | I27: ='2021'!I13 -> 3 | ... AC27: ='2021'!AC13 -> 1
A28: =ÖSSZES!$A$3 -> Csuka Lajos | G28: X | H28: X | O28: X | P28: X | W28: X | X28: X | AH28: =1*COUNTIF(A28:AF28,"+") -> 0 | AI28: =1*COUNTIF(B28:AF28,"szf") -> 0
A29: =ÖSSZES!$A$4 -> Batiz Attila | G29: X | H29: X | O29: X | P29: X | W29: X | X29: X | AH29: =1*COUNTIF(A29:AF29,"+") -> 0 | AI29: =1*COUNTIF(B29:AF29,"szf") -> 0
A30: =ÖSSZES!$A$5 -> Füredi Antal | G30: X | H30: X | O30: X | P30: X | W30: X | X30: X | AH30: =1*COUNTIF(A30:AF30,"+") -> 0 | AI30: =1*COUNTIF(B30:AF30,"szf") -> 0
A31: =ÖSSZES!$A$6 -> Iványi István | G31: X | H31: X | O31: X | P31: X | W31: X | X31: X | AH31: =1*COUNTIF(A31:AF31,"+") -> 0 | AI31: =1*COUNTIF(B31:AF31,"szf") -> 0
A32: =ÖSSZES!$A$7 -> Katonka Tibor | G32: X | H32: X | O32: X | P32: X | W32: X | X32: X | AH32: =1*COUNTIF(A32:AF32,"+") -> 0 | AI32: =1*COUNTIF(B32:AF32,"szf") -> 0
A33: =ÖSSZES!$A$8 -> Mizsák Péter | G33: X | H33: X | O33: X | P33: X | W33: X | X33: X | AH33: =1*COUNTIF(A33:AF33,"+") -> 0 | AI33: =1*COUNTIF(B33:AF33,"szf") -> 0
A34: =ÖSSZES!$A$9 -> Vatamány Gergő | G34: X | H34: X | O34: X | P34: X | W34: X | X34: X | AH34: =1*COUNTIF(A34:AF34,"+") -> 0 | AI34: =1*COUNTIF(B34:AF34,"szf") -> 0
A35: =ÖSSZES!$A$10 -> Név8 | G35: X | H35: X | O35: X | P35: X | W35: X | X35: X | AH35: =1*COUNTIF(A35:AF35,"+") -> 0 | AI35: =1*COUNTIF(B35:AF35,"szf") -> 0
A36: =ÖSSZES!$A$11 -> Név9 | G36: X | H36: X | O36: X | P36: X | W36: X | X36: X | AH36: =1*COUNTIF(A36:AF36,"+") -> 0 | AI36: =1*COUNTIF(B36:AF36,"szf") -> 0
A37: =ÖSSZES!$A$12 -> Név10 | G37: X | H37: X | O37: X | P37: X | W37: X | X37: X | AH37: =1*COUNTIF(A37:AF37,"+") -> 0 | AI37: =1*COUNTIF(B37:AF37,"szf") -> 0
A38: =ÖSSZES!$A$13 -> Név11 | G38: X | H38: X | O38: X | P38: X | W38: X | X38: X | AH38: =1*COUNTIF(A38:AF38,"+") -> 0 | AI38: =1*COUNTIF(B38:AF38,"szf") -> 0
A39: =ÖSSZES!$A$14 -> Név12 | G39: X | H39: X | O39: X | P39: X | W39: X | X39: X | AH39: =1*COUNTIF(A39:AF39,"+") -> 0 | AI39: =1*COUNTIF(B39:AF39,"szf") -> 0
A40: =ÖSSZES!$A$15 -> Név13 | G40: X | H40: X | O40: X | P40: X | W40: X | X40: X | AH40: =1*COUNTIF(A40:AF40,"+") -> 0 | AI40: =1*COUNTIF(B40:AF40,"szf") -> 0
A41: =ÖSSZES!$A$16 -> Név14 | G41: X | H41: X | O41: X | P41: X | W41: X | X41: X | AH41: =1*COUNTIF(A41:AF41,"+") -> 0 | AI41: =1*COUNTIF(B41:AF41,"szf") -> 0
...

Sheet B
A1: JANUÁR | B1: 1 | C1: 2 | D1: 3 | E1: 4 | F1: 5 | G1: 6 | H1: 7 | I1: 8 | J1: 9 | K1: 10 | L1: 11 | M1: 12 | N1: 13 | O1: 14 | P1: 15 | Q1: 16 | R1: 17 | S1: 18 | T1: 19 | U1: 20 | V1: 21 | W1: 22 | X1: 23 | Y1: 24 | Z1: 25 | AA1: 26 | AB1: 27 | AC1: 28 | AD1: 29 | AE1: 30 | AF1: 31 | AH1: + | AI1: SZF
B2: ='2021'!B4 -> P | C2: ='2021'!C4 -> Szo | D2: ='2021'!D4 -> V | E2: ='2021'!E4 -> H | F2: ='2021'!F4 -> K | G2: ='2021'!G4 -> Sze | H2: ='2021'!H4 -> Cs | I2: ='2021'!I4 -> P | ... AF2: ='2021'!AF4 -> V
B3: ='2021'!B6 -> 3 | C3: ='2021'!C6 -> 3 | D3: ='2021'!D6 -> X | E3: ='2021'!E6 -> X | F3: ='2021'!F6 -> 2 | G3: ='2021'!G6 -> 2 | H3: ='2021'!H6 -> 2 | I3: ='2021'!I6 -> 2 | ... AF3: ='2021'!AF6 -> 2
A4: =ÖSSZES!$A$26 -> Katona László | D4: X | E4: X | L4: X | M4: X | T4: X | U4: X | AB4: X | AC4: X | AH4: =1*COUNTIF(A4:AF4,"+") -> 0 | AI4: =1*COUNTIF(B4:AF4,"szf") -> 0
A5: =ÖSSZES!$A$27 -> Fényi László | D5: X | E5: X | L5: X | M5: X | T5: X | U5: X | AB5: X | AC5: X | AH5: =1*COUNTIF(A5:AF5,"+") -> 0 | AI5: =1*COUNTIF(B5:AF5,"szf") -> 0
A6: =ÖSSZES!$A$28 -> Habara Gábor | D6: X | E6: X | L6: X | M6: X | T6: X | U6: X | AB6: X | AC6: X | AH6: =1*COUNTIF(A6:AF6,"+") -> 0 | AI6: =1*COUNTIF(B6:AF6,"szf") -> 0
A7: =ÖSSZES!$A$29 -> Holba Imre | D7: X | E7: X | L7: X | M7: X | T7: X | U7: X | AB7: X | AC7: X | AH7: =1*COUNTIF(A7:AF7,"+") -> 0 | AI7: =1*COUNTIF(B7:AF7,"szf") -> 0
A8: =ÖSSZES!$A$30 -> Király Bálint Donát | D8: X | E8: X | L8: X | M8: X | T8: X | U8: X | AB8: X | AC8: X | AH8: =1*COUNTIF(A8:AF8,"+") -> 0 | AI8: =1*COUNTIF(B8:AF8,"szf") -> 0
A9: =ÖSSZES!$A$31 -> Kiss János Tamás | D9: X | E9: X | L9: X | M9: X | T9: X | U9: X | AB9: X | AC9: X | AH9: =1*COUNTIF(A9:AF9,"+") -> 0 | AI9: =1*COUNTIF(B9:AF9,"szf") -> 0
A10: =ÖSSZES!$A$32 -> Mezei Lajos | D10: X | E10: X | L10: X | M10: X | T10: X | U10: X | AB10: X | AC10: X | AH10: =1*COUNTIF(A10:AF10,"+") -> 0 | AI10: =1*COUNTIF(B10:AF10,"szf") -> 0
A11: =ÖSSZES!$A$33 -> Név8 | D11: X | E11: X | L11: X | M11: X | T11: X | U11: X | AB11: X | AC11: X | AH11: =1*COUNTIF(A11:AF11,"+") -> 0 | AI11: =1*COUNTIF(B11:AF11,"szf") -> 0
A12: =ÖSSZES!$A$34 -> Név9 | D12: X | E12: X | L12: X | M12: X | T12: X | U12: X | AB12: X | AC12: X | AH12: =1*COUNTIF(A12:AF12,"+") -> 0 | AI12: =1*COUNTIF(B12:AF12,"szf") -> 0
A13: =ÖSSZES!$A$35 -> Név10 | D13: X | E13: X | L13: X | M13: X | T13: X | U13: X | AB13: X | AC13: X | AH13: =1*COUNTIF(A13:AF13,"+") -> 0 | AI13: =1*COUNTIF(B13:AF13,"szf") -> 0
A14: =ÖSSZES!$A$36 -> Név11 | D14: X | E14: X | L14: X | M14: X | T14: X | U14: X | AB14: X | AC14: X | AH14: =1*COUNTIF(A14:AF14,"+") -> 0 | AI14: =1*COUNTIF(B14:AF14,"szf") -> 0
A15: =ÖSSZES!$A$37 -> Név12 | D15: X | E15: X | L15: X | M15: X | T15: X | U15: X | AB15: X | AC15: X | AH15: =1*COUNTIF(A15:AF15,"+") -> 0 | AI15: =1*COUNTIF(B15:AF15,"szf") -> 0
A16: =ÖSSZES!$A$38 -> Név13 | D16: X | E16: X | L16: X | M16: X | T16: X | U16: X | AB16: X | AC16: X | AH16: =1*COUNTIF(A16:AF16,"+") -> 0 | AI16: =1*COUNTIF(B16:AF16,"szf") -> 0
A17: =ÖSSZES!$A$39 -> Név14 | D17: X | E17: X | L17: X | M17: X | T17: X | U17: X | AB17: X | AC17: X | AH17: =1*COUNTIF(A17:AF17,"+") -> 0 | AI17: =1*COUNTIF(B17:AF17,"szf") -> 0
A18: =ÖSSZES!$A$40 -> Név15 | D18: X | E18: X | L18: X | M18: X | T18: X | U18: X | AB18: X | AC18: X | AH18: =1*COUNTIF(A18:AF18,"+") -> 0 | AI18: =1*COUNTIF(B18:AF18,"szf") -> 0
A19: =ÖSSZES!$A$41 -> Név16 | D19: X | E19: X | L19: X | M19: X | T19: X | U19: X | AB19: X | AC19: X | AH19: =1*COUNTIF(A19:AF19,"+") -> 0 | AI19: =1*COUNTIF(B19:AF19,"szf") -> 0
A20: =ÖSSZES!$A$42 -> Név17 | D20: X | E20: X | L20: X | M20: X | T20: X | U20: X | AB20: X | AC20: X | AH20: =1*COUNTIF(A20:AF20,"+") -> 0 | AI20: =1*COUNTIF(B20:AF20,"szf") -> 0
A21: =ÖSSZES!$A$43 -> Név18 | D21: X | E21: X | L21: X | M21: X | T21: X | U21: X | AB21: X | AC21: X | AH21: =1*COUNTIF(A21:AF21,"+") -> 0 | AI21: =1*COUNTIF(B21:AF21,"szf") -> 0
A22: =ÖSSZES!$A$44 -> Név19 | D22: X | E22: X | L22: X | M22: X | T22: X | U22: X | AB22: X | AC22: X | AH22: =1*COUNTIF(A22:AF22,"+") -> 0 | AI22: =1*COUNTIF(B22:AF22,"szf") -> 0
A23: =ÖSSZES!$A$45 -> Név20 | D23: X | E23: X | L23: X | M23: X | T23: X | U23: X | AB23: X | AC23: X | AH23: =1*COUNTIF(A23:AF23,"+") -> 0 | AI23: =1*COUNTIF(B23:AF23,"szf") -> 0
A25: FEBRUÁR | B25: 1 | C25: 2 | D25: 3 | E25: 4 | F25: 5 | G25: 6 | H25: 7 | I25: 8 | J25: 9 | K25: 10 | L25: 11 | M25: 12 | N25: 13 | O25: 14 | P25: 15 | Q25: 16 | R25: 17 | S25: 18 | T25: 19 | U25: 20 | V25: 21 | W25: 22 | X25: 23 | Y25: 24 | Z25: 25 | AA25: 26 | AB25: 27 | AC25: 28 | AH25: + | AI25: SZF
B26: ='2021'!B12 -> H | C26: ='2021'!C12 -> K | D26: ='2021'!D12 -> Sze | E26: ='2021'!E12 -> Cs | F26: ='2021'!F12 -> P | G26: ='2021'!G12 -> Szo | H26: ='2021'!H12 -> V | I26: ='2021'!I12 -> H | ... AC26: ='2021'!AC12 -> V
B27: ='2021'!B14 -> 2 | C27: ='2021'!C14 -> 2 | D27: ='2021'!D14 -> 2 | E27: ='2021'!E14 -> X | F27: ='2021'!F14 -> X | G27: ='2021'!G14 -> 1 | H27: ='2021'!H14 -> 1 | I27: ='2021'!I14 -> 1 | ... AC27: ='2021'!AC14 -> X
A28: =ÖSSZES!$A$26 -> Katona László | E28: X | F28: X | M28: X | N28: X | U28: X | V28: X | AC28: X | AH28: =1*COUNTIF(A28:AF28,"+") -> 0 | AI28: =1*COUNTIF(B28:AF28,"szf") -> 0
A29: =ÖSSZES!$A$27 -> Fényi László | E29: X | F29: X | M29: X | N29: X | U29: X | V29: X | AC29: X | AH29: =1*COUNTIF(A29:AF29,"+") -> 0 | AI29: =1*COUNTIF(B29:AF29,"szf") -> 0
A30: =ÖSSZES!$A$28 -> Habara Gábor | E30: X | F30: X | M30: X | N30: X | U30: X | V30: X | AC30: X | AH30: =1*COUNTIF(A30:AF30,"+") -> 0 | AI30: =1*COUNTIF(B30:AF30,"szf") -> 0
A31: =ÖSSZES!$A$29 -> Holba Imre | E31: X | F31: X | M31: X | N31: X | U31: X | V31: X | AC31: X | AH31: =1*COUNTIF(A31:AF31,"+") -> 0 | AI31: =1*COUNTIF(B31:AF31,"szf") -> 0
A32: =ÖSSZES!$A$30 -> Király Bálint Donát | E32: X | F32: X | M32: X | N32: X | U32: X | V32: X | AC32: X | AH32: =1*COUNTIF(A32:AF32,"+") -> 0 | AI32: =1*COUNTIF(B32:AF32,"szf") -> 0
A33: =ÖSSZES!$A$31 -> Kiss János Tamás | E33: X | F33: X | M33: X | N33: X | U33: X | V33: X | AC33: X | AH33: =1*COUNTIF(A33:AF33,"+") -> 0 | AI33: =1*COUNTIF(B33:AF33,"szf") -> 0
A34: =ÖSSZES!$A$32 -> Mezei Lajos | E34: X | F34: X | M34: X | N34: X | U34: X | V34: X | AC34: X | AH34: =1*COUNTIF(A34:AF34,"+") -> 0 | AI34: =1*COUNTIF(B34:AF34,"szf") -> 0
A35: =ÖSSZES!$A$33 -> Név8 | E35: X | F35: X | M35: X | N35: X | U35: X | V35: X | AC35: X | AH35: =1*COUNTIF(A35:AF35,"+") -> 0 | AI35: =1*COUNTIF(B35:AF35,"szf") -> 0
A36: =ÖSSZES!$A$34 -> Név9 | E36: X | F36: X | M36: X | N36: X | U36: X | V36: X | AC36: X | AH36: =1*COUNTIF(A36:AF36,"+") -> 0 | AI36: =1*COUNTIF(B36:AF36,"szf") -> 0
A37: =ÖSSZES!$A$35 -> Név10 | E37: X | F37: X | M37: X | N37: X | U37: X | V37: X | AC37: X | AH37: =1*COUNTIF(A37:AF37,"+") -> 0 | AI37: =1*COUNTIF(B37:AF37,"szf") -> 0
A38: =ÖSSZES!$A$36 -> Név11 | E38: X | F38: X | M38: X | N38: X | U38: X | V38: X | AC38: X | AH38: =1*COUNTIF(A38:AF38,"+") -> 0 | AI38: =1*COUNTIF(B38:AF38,"szf") -> 0
A39: =ÖSSZES!$A$37 -> Név12 | E39: X | F39: X | M39: X | N39: X | U39: X | V39: X | AC39: X | AH39: =1*COUNTIF(A39:AF39,"+") -> 0 | AI39: =1*COUNTIF(B39:AF39,"szf") -> 0
A40: =ÖSSZES!$A$38 -> Név13 | E40: X | F40: X | M40: X | N40: X | U40: X | V40: X | AC40: X | AH40: =1*COUNTIF(A40:AF40,"+") -> 0 | AI40: =1*COUNTIF(B40:AF40,"szf") -> 0
A41: =ÖSSZES!$A$39 -> Név14 | E41: X | F41: X | M41: X | N41: X | U41: X | V41: X | AC41: X | AH41: =1*COUNTIF(A41:AF41,"+") -> 0 | AI41: =1*COUNTIF(B41:AF41,"szf") -> 0
...

Sheet C
A1: JANUÁR | B1: 1 | C1: 2 | D1: 3 | E1: 4 | F1: 5 | G1: 6 | H1: 7 | I1: 8 | J1: 9 | K1: 10 | L1: 11 | M1: 12 | N1: 13 | O1: 14 | P1: 15 | Q1: 16 | R1: 17 | S1: 18 | T1: 19 | U1: 20 | V1: 21 | W1: 22 | X1: 23 | Y1: 24 | Z1: 25 | AA1: 26 | AB1: 27 | AC1: 28 | AD1: 29 | AE1: 30 | AF1: 31 | AH1: + | AI1: SZF
B2: ='2021'!B4 -> P | C2: ='2021'!C4 -> Szo | D2: ='2021'!D4 -> V | E2: ='2021'!E4 -> H | F2: ='2021'!F4 -> K | G2: ='2021'!G4 -> Sze | H2: ='2021'!H4 -> Cs | I2: ='2021'!I4 -> P | ... AF2: ='2021'!AF4 -> V
B3: ='2021'!B7 -> X | C3: ='2021'!C7 -> X | D3: ='2021'!D7 -> 3 | E3: ='2021'!E7 -> 3 | F3: ='2021'!F7 -> 3 | G3: ='2021'!G7 -> 3 | H3: ='2021'!H7 -> 3 | I3: ='2021'!I7 -> 3 | ... AF3: ='2021'!AF7 -> 3
A4: =ÖSSZES!$A$49 -> Kuik-Filep András | B4: X | C4: X | J4: X | K4: X | R4: X | S4: X | Z4: X | AA4: X | AH4: =1*COUNTIF(A4:AF4,"+") -> 0 | AI4: =1*COUNTIF(B4:AF4,"szf") -> 0
A5: =ÖSSZES!$A$50 -> Balogh Zsolt | B5: X | C5: X | J5: X | K5: X | R5: X | S5: X | Z5: X | AA5: X | AH5: =1*COUNTIF(A5:AF5,"+") -> 0 | AI5: =1*COUNTIF(B5:AF5,"szf") -> 0
A6: =ÖSSZES!$A$51 -> Éliás Viktor | B6: X | C6: X | J6: X | K6: X | R6: X | S6: X | Z6: X | AA6: X | AH6: =1*COUNTIF(A6:AF6,"+") -> 0 | AI6: =1*COUNTIF(B6:AF6,"szf") -> 0
A7: =ÖSSZES!$A$52 -> Hadházi Kálmán | B7: X | C7: X | D7: + | J7: X | K7: X | R7: X | S7: X | Z7: X | AA7: X | AH7: =1*COUNTIF(A7:AF7,"+") -> 1 | AI7: =1*COUNTIF(B7:AF7,"szf") -> 0
A8: =ÖSSZES!$A$53 -> Kiss Attila | B8: X | C8: X | J8: X | K8: X | R8: X | S8: X | Z8: X | AA8: X | AH8: =1*COUNTIF(A8:AF8,"+") -> 0 | AI8: =1*COUNTIF(B8:AF8,"szf") -> 0
A9: =ÖSSZES!$A$54 -> Serestyén Dániel | B9: X | C9: X | J9: X | K9: X | R9: X | S9: X | Z9: X | AA9: X | AH9: =1*COUNTIF(A9:AF9,"+") -> 0 | AI9: =1*COUNTIF(B9:AF9,"szf") -> 0
A10: =ÖSSZES!$A$55 -> Varga Imre | B10: X | C10: X | E10: + | F10: szf | J10: X | K10: X | R10: X | S10: X | Z10: X | AA10: X | AH10: =1*COUNTIF(A10:AF10,"+") -> 1 | AI10: =1*COUNTIF(B10:AF10,"szf") -> 1
A11: =ÖSSZES!$A$56 -> Név8 | B11: X | C11: X | J11: X | K11: X | R11: X | S11: X | Z11: X | AA11: X | AH11: =1*COUNTIF(A11:AF11,"+") -> 0 | AI11: =1*COUNTIF(B11:AF11,"szf") -> 0
A12: =ÖSSZES!$A$57 -> Név9 | B12: X | C12: X | J12: X | K12: X | R12: X | S12: X | Z12: X | AA12: X | AH12: =1*COUNTIF(A12:AF12,"+") -> 0 | AI12: =1*COUNTIF(B12:AF12,"szf") -> 0
A13: =ÖSSZES!$A$58 -> Név10 | B13: X | C13: X | J13: X | K13: X | R13: X | S13: X | Z13: X | AA13: X | AH13: =1*COUNTIF(A13:AF13,"+") -> 0 | AI13: =1*COUNTIF(B13:AF13,"szf") -> 0
A14: =ÖSSZES!$A$59 -> Név11 | B14: X | C14: X | J14: X | K14: X | R14: X | S14: X | Z14: X | AA14: X | AH14: =1*COUNTIF(A14:AF14,"+") -> 0 | AI14: =1*COUNTIF(B14:AF14,"szf") -> 0
A15: =ÖSSZES!$A$60 -> Név12 | B15: X | C15: X | J15: X | K15: X | R15: X | S15: X | Z15: X | AA15: X | AH15: =1*COUNTIF(A15:AF15,"+") -> 0 | AI15: =1*COUNTIF(B15:AF15,"szf") -> 0
A16: =ÖSSZES!$A$61 -> Név13 | B16: X | C16: X | J16: X | K16: X | R16: X | S16: X | Z16: X | AA16: X | AH16: =1*COUNTIF(A16:AF16,"+") -> 0 | AI16: =1*COUNTIF(B16:AF16,"szf") -> 0
A17: =ÖSSZES!$A$62 -> Név14 | B17: X | C17: X | J17: X | K17: X | R17: X | S17: X | Z17: X | AA17: X | AH17: =1*COUNTIF(A17:AF17,"+") -> 0 | AI17: =1*COUNTIF(B17:AF17,"szf") -> 0
A18: =ÖSSZES!$A$63 -> Név15 | B18: X | C18: X | J18: X | K18: X | R18: X | S18: X | Z18: X | AA18: X | AH18: =1*COUNTIF(A18:AF18,"+") -> 0 | AI18: =1*COUNTIF(B18:AF18,"szf") -> 0
A19: =ÖSSZES!$A$64 -> Név16 | B19: X | C19: X | J19: X | K19: X | R19: X | S19: X | Z19: X | AA19: X | AH19: =1*COUNTIF(A19:AF19,"+") -> 0 | AI19: =1*COUNTIF(B19:AF19,"szf") -> 0
A20: =ÖSSZES!$A$65 -> Név17 | B20: X | C20: X | J20: X | K20: X | R20: X | S20: X | Z20: X | AA20: X | AH20: =1*COUNTIF(A20:AF20,"+") -> 0 | AI20: =1*COUNTIF(B20:AF20,"szf") -> 0
A21: =ÖSSZES!$A$66 -> Név18 | B21: X | C21: X | J21: X | K21: X | R21: X | S21: X | Z21: X | AA21: X | AH21: =1*COUNTIF(A21:AF21,"+") -> 0 | AI21: =1*COUNTIF(B21:AF21,"szf") -> 0
A22: =ÖSSZES!$A$67 -> Név19 | B22: X | C22: X | J22: X | K22: X | R22: X | S22: X | Z22: X | AA22: X | AH22: =1*COUNTIF(A22:AF22,"+") -> 0 | AI22: =1*COUNTIF(B22:AF22,"szf") -> 0
A23: =ÖSSZES!$A$68 -> Név20 | B23: X | C23: X | J23: X | K23: X | R23: X | S23: X | Z23: X | AA23: X | AH23: =1*COUNTIF(A23:AF23,"+") -> 0 | AI23: =1*COUNTIF(B23:AF23,"szf") -> 0
A25: FEBRUÁR | B25: 1 | C25: 2 | D25: 3 | E25: 4 | F25: 5 | G25: 6 | H25: 7 | I25: 8 | J25: 9 | K25: 10 | L25: 11 | M25: 12 | N25: 13 | O25: 14 | P25: 15 | Q25: 16 | R25: 17 | S25: 18 | T25: 19 | U25: 20 | V25: 21 | W25: 22 | X25: 23 | Y25: 24 | Z25: 25 | AA25: 26 | AB25: 27 | AC25: 28 | AH25: + | AI25: SZF
B26: ='2021'!B12 -> H | C26: ='2021'!C12 -> K | D26: ='2021'!D12 -> Sze | E26: ='2021'!E12 -> Cs | F26: ='2021'!F12 -> P | G26: ='2021'!G12 -> Szo | H26: ='2021'!H12 -> V | I26: ='2021'!I12 -> H | ... AC26: ='2021'!AC12 -> V
B27: ='2021'!B15 -> 3 | C27: ='2021'!C15 -> X | D27: ='2021'!D15 -> X | E27: ='2021'!E15 -> 2 | F27: ='2021'!F15 -> 2 | G27: ='2021'!G15 -> 2 | H27: ='2021'!H15 -> 2 | I27: ='2021'!I15 -> 2 | ... AC27: ='2021'!AC15 -> 2
A28: =ÖSSZES!$A$49 -> Kuik-Filep András | C28: X | D28: X | K28: X | L28: X | S28: X | T28: X | AA28: X | AB28: X | AH28: =1*COUNTIF(A28:AF28,"+") -> 0 | AI28: =1*COUNTIF(B28:AF28,"szf") -> 0
A29: =ÖSSZES!$A$50 -> Balogh Zsolt | C29: X | D29: X | K29: X | L29: X | S29: X | T29: X | AA29: X | AB29: X | AH29: =1*COUNTIF(A29:AF29,"+") -> 0 | AI29: =1*COUNTIF(B29:AF29,"szf") -> 0
A30: =ÖSSZES!$A$51 -> Éliás Viktor | C30: X | D30: X | K30: X | L30: X | S30: X | T30: X | AA30: X | AB30: X | AH30: =1*COUNTIF(A30:AF30,"+") -> 0 | AI30: =1*COUNTIF(B30:AF30,"szf") -> 0
A31: =ÖSSZES!$A$52 -> Hadházi Kálmán | C31: X | D31: X | K31: X | L31: X | S31: X | T31: X | AA31: X | AB31: X | AH31: =1*COUNTIF(A31:AF31,"+") -> 0 | AI31: =1*COUNTIF(B31:AF31,"szf") -> 0
A32: =ÖSSZES!$A$53 -> Kiss Attila | C32: X | D32: X | K32: X | L32: X | S32: X | T32: X | AA32: X | AB32: X | AH32: =1*COUNTIF(A32:AF32,"+") -> 0 | AI32: =1*COUNTIF(B32:AF32,"szf") -> 0
A33: =ÖSSZES!$A$54 -> Serestyén Dániel | C33: X | D33: X | K33: X | L33: X | S33: X | T33: X | AA33: X | AB33: X | AH33: =1*COUNTIF(A33:AF33,"+") -> 0 | AI33: =1*COUNTIF(B33:AF33,"szf") -> 0
A34: =ÖSSZES!$A$55 -> Varga Imre | C34: X | D34: X | K34: X | L34: X | S34: X | T34: X | AA34: X | AB34: X | AH34: =1*COUNTIF(A34:AF34,"+") -> 0 | AI34: =1*COUNTIF(B34:AF34,"szf") -> 0
A35: =ÖSSZES!$A$56 -> Név8 | C35: X | D35: X | K35: X | L35: X | S35: X | T35: X | AA35: X | AB35: X | AH35: =1*COUNTIF(A35:AF35,"+") -> 0 | AI35: =1*COUNTIF(B35:AF35,"szf") -> 0
A36: =ÖSSZES!$A$57 -> Név9 | C36: X | D36: X | K36: X | L36: X | S36: X | T36: X | AA36: X | AB36: X | AH36: =1*COUNTIF(A36:AF36,"+") -> 0 | AI36: =1*COUNTIF(B36:AF36,"szf") -> 0
A37: =ÖSSZES!$A$58 -> Név10 | C37: X | D37: X | K37: X | L37: X | S37: X | T37: X | AA37: X | AB37: X | AH37: =1*COUNTIF(A37:AF37,"+") -> 0 | AI37: =1*COUNTIF(B37:AF37,"szf") -> 0
A38: =ÖSSZES!$A$59 -> Név11 | C38: X | D38: X | K38: X | L38: X | S38: X | T38: X | AA38: X | AB38: X | AH38: =1*COUNTIF(A38:AF38,"+") -> 0 | AI38: =1*COUNTIF(B38:AF38,"szf") -> 0
